Workbook

Sheet 00_TONG_QUAN
A1: BẢNG TỔNG HỢP YÊU CẦU PWA SƠN CẢNG — V3
A2: 11/10/2026 | Đã nhập nguyên văn phản hồi V1 đúng; bổ sung đăng ký cắm điện trước khi cont vào và chỉnh số cont.
A4: TIẾN ĐỘ XÁC NHẬN
A5: TỔNG CÂU HỎI | C5: ĐÃ CÓ LỰA CHỌN | E5: CẦN LÀM RÕ | G5: P0 CẦN XỬ LÝ | I5: ĐỦ RÕ ĐẶC TẢ
A6: =COUNTA('01_CAU_HOI'!$A$5:$A$250) | C6: =COUNTIF('01_CAU_HOI'!$F$5:$F$250,"<>") | E6: =COUNTIF('01_CAU_HOI'!$N$5:$N$250,"Cần làm rõ") | G6: =COUNTIFS('01_CAU_HOI'!$C$5:$C$250,"P0",'01_CAU_HOI'!$N$5:$N$250,"Cần làm rõ")+COUNTIFS('01_CAU_HOI'!$C$5:$C$250,"P0",'01_CAU_HOI'!$N$5:$N$250,"Chưa trả lời") | I6: =IFERROR(COUNTIF('01_CAU_HOI'!$N$5:$N$250,"Đủ rõ để đặc tả")/A6,0)
A8: CÁCH ĐIỀN FILE
A9: 1. Mở 01_CAU_HOI: F/G/H giữ NGUYÊN phản hồi V1 của bạn; không cần nhập lại.
A10: 2. Lọc N = Cần làm rõ/Chưa trả lời; hoặc vào 11_RA_SOAT_V1 để bổ sung quyết định và giải thích.
A11: 3. Những câu PR/SC liên quan container dự kiến, sai số cont đã được đưa từ V2 sang và vẫn giữ trạng thái đúng.
A12: 4. 02_DA_CHOT tổng hợp các nguyên tắc được xác nhận; 12_TRA_LOI_V1_GOC lưu nguyên các câu trả lời V1 để đối chiếu.
A13: 5. Tiếp tục rà soát giá/thu tiền/ngoại lệ cho ra; KHÔNG xem mọi ô H=Đã chốt là đặc tả đã đủ rõ.
A14: 6. Dùng 04_PHAN_QUYEN để gán quyền, 05_KICH_BAN để kiểm thử, 09_TINH_DIEN để thử tiền điện 15 phút.
A15: 7. Sử dụng các tab tham chiếu: giá, tài khoản, mapping, đối soát và quy trình dự kiến/sửa số cont.
A18: TỔNG HỢP THEO NHÓM
A19: Nhóm nghiệp vụ | D19: Tổng | F19: Đủ rõ | H19: Cần xử lý
A20: 01. Vé xe / cổng | D20: =COUNTIF('01_CAU_HOI'!$B$5:$B$250,A20) | F20: =COUNTIFS('01_CAU_HOI'!$B$5:$B$250,A20,'01_CAU_HOI'!$N$5:$N$250,"Đủ rõ để đặc tả") | H20: =COUNTIFS('01_CAU_HOI'!$B$5:$B$250,A20,'01_CAU_HOI'!$N$5:$N$250,"Cần làm rõ")+COUNTIFS('01_CAU_HOI'!$B$5:$B$250,A20,'01_CAU_HOI'!$N$5:$N$250,"Chưa trả lời")
A21: 02. Lưu container | D21: =COUNTIF('01_CAU_HOI'!$B$5:$B$250,A21) | F21: =COUNTIFS('01_CAU_HOI'!$B$5:$B$250,A21,'01_CAU_HOI'!$N$5:$N$250,"Đủ rõ để đặc tả") | H21: =COUNTIFS('01_CAU_HOI'!$B$5:$B$250,A21,'01_CAU_HOI'!$N$5:$N$250,"Cần làm rõ")+COUNTIFS('01_CAU_HOI'!$B$5:$B$250,A21,'01_CAU_HOI'!$N$5:$N$250,"Chưa trả lời")
A22: 03. Cắm/rút điện | D22: =COUNTIF('01_CAU_HOI'!$B$5:$B$250,A22) | F22: =COUNTIFS('01_CAU_HOI'!$B$5:$B$250,A22,'01_CAU_HOI'!$N$5:$N$250,"Đủ rõ để đặc tả") | H22: =COUNTIFS('01_CAU_HOI'!$B$5:$B$250,A22,'01_CAU_HOI'!$N$5:$N$250,"Cần làm rõ")+COUNTIFS('01_CAU_HOI'!$B$5:$B$250,A22,'01_CAU_HOI'!$N$5:$N$250,"Chưa trả lời")
A23: 04. Thanh toán | D23: =COUNTIF('01_CAU_HOI'!$B$5:$B$250,A23) | F23: =COUNTIFS('01_CAU_HOI'!$B$5:$B$250,A23,'01_CAU_HOI'!$N$5:$N$250,"Đủ rõ để đặc tả") | H23: =COUNTIFS('01_CAU_HOI'!$B$5:$B$250,A23,'01_CAU_HOI'!$N$5:$N$250,"Cần làm rõ")+COUNTIFS('01_CAU_HOI'!$B$5:$B$250,A23,'01_CAU_HOI'!$N$5:$N$250,"Chưa trả lời")
A24: 05. Phân quyền | D24: =COUNTIF('01_CAU_HOI'!$B$5:$B$250,A24) | F24: =COUNTIFS('01_CAU_HOI'!$B$5:$B$250,A24,'01_CAU_HOI'!$N$5:$N$250,"Đủ rõ để đặc tả") | H24: =COUNTIFS('01_CAU_HOI'!$B$5:$B$250,A24,'01_CAU_HOI'!$N$5:$N$250,"Cần làm rõ")+COUNTIFS('01_CAU_HOI'!$B$5:$B$250,A24,'01_CAU_HOI'!$N$5:$N$250,"Chưa trả lời")
A25: 06. Điều phối / container | D25: =COUNTIF('01_CAU_HOI'!$B$5:$B$250,A25) | F25: =COUNTIFS('01_CAU_HOI'!$B$5:$B$250,A25,'01_CAU_HOI'!$N$5:$N$250,"Đủ rõ để đặc tả") | H25: =COUNTIFS('01_CAU_HOI'!$B$5:$B$250,A25,'01_CAU_HOI'!$N$5:$N$250,"Cần làm rõ")+COUNTIFS('01_CAU_HOI'!$B$5:$B$250,A25,'01_CAU_HOI'!$N$5:$N$250,"Chưa trả lời")
A26: 07. Báo cáo / đối soát | D26: =COUNTIF('01_CAU_HOI'!$B$5:$B$250,A26) | F26: =COUNTIFS('01_CAU_HOI'!$B$5:$B$250,A26,'01_CAU_HOI'!$N$5:$N$250,"Đủ rõ để đặc tả") | H26: =COUNTIFS('01_CAU_HOI'!$B$5:$B$250,A26,'01_CAU_HOI'!$N$5:$N$250,"Cần làm rõ")+COUNTIFS('01_CAU_HOI'!$B$5:$B$250,A26,'01_CAU_HOI'!$N$5:$N$250,"Chưa trả lời")
A27: 08. Kỹ thuật / bảo mật | D27: =COUNTIF('01_CAU_HOI'!$B$5:$B$250,A27) | F27: =COUNTIFS('01_CAU_HOI'!$B$5:$B$250,A27,'01_CAU_HOI'!$N$5:$N$250,"Đủ rõ để đặc tả") | H27: =COUNTIFS('01_CAU_HOI'!$B$5:$B$250,A27,'01_CAU_HOI'!$N$5:$N$250,"Cần làm rõ")+COUNTIFS('01_CAU_HOI'!$B$5:$B$250,A27,'01_CAU_HOI'!$N$5:$N$250,"Chưa trả lời")
A28: 09. Chuyển dữ liệu | D28: =COUNTIF('01_CAU_HOI'!$B$5:$B$250,A28) | F28: =COUNTIFS('01_CAU_HOI'!$B$5:$B$250,A28,'01_CAU_HOI'!$N$5:$N$250,"Đủ rõ để đặc tả") | H28: =COUNTIFS('01_CAU_HOI'!$B$5:$B$250,A28,'01_CAU_HOI'!$N$5:$N$250,"Cần làm rõ")+COUNTIFS('01_CAU_HOI'!$B$5:$B$250,A28,'01_CAU_HOI'!$N$5:$N$250,"Chưa trả lời")
A29: 10. Nghiệm thu / triển khai | D29: =COUNTIF('01_CAU_HOI'!$B$5:$B$250,A29) | F29: =COUNTIFS('01_CAU_HOI'!$B$5:$B$250,A29,'01_CAU_HOI'!$N$5:$N$250,"Đủ rõ để đặc tả") | H29: =COUNTIFS('01_CAU_HOI'!$B$5:$B$250,A29,'01_CAU_HOI'!$N$5:$N$250,"Cần làm rõ")+COUNTIFS('01_CAU_HOI'!$B$5:$B$250,A29,'01_CAU_HOI'!$N$5:$N$250,"Chưa trả lời")
A32: LƯU Ý: 98 dòng V1 được giữ nguyên trạng thái người dùng tự đánh dấu; cột RÀ SOÁT mới là thước đo độ đủ rõ để lập trình.
A34: DỮ LIỆU GỐC: PRICE_LIST và USERS do Sơn Cảng cung cấp; VEHICLE 315 bản ghi, CONTAINER 259 bản ghi (tính từ các tệp đính kèm).
A35: BẢN V1 TRẢ LỜI ĐÚNG ĐÃ NHẬP: Untitled spreadsheet (1).xlsx | Không tự sửa dữ liệu gốc; mọi điểm xung đột được đánh dấu.
A36: Đi tới bảng CÂU HỎI | D36: Đi tới các quyết định ĐÃ CHỐT | G36: Đi tới MA TRẬN PHÂN QUYỀN
A38: Đi tới BẢNG GIÁ | D38: Đi tới TÌNH HUỐNG UAT | G38: Đi tới MÔ PHỎNG TIỀN ĐIỆN

Sheet 01_CAU_HOI
A1: BẢNG CÂU HỎI PWA SƠN CẢNG — ĐÃ HỢP NHẤT TRẢ LỜI V1
A2: Cột F/G/H: dữ liệu trả lời nguyên văn từ V1; cột N/O: kết quả rà soát của trợ lý. Cần làm rõ KHÔNG đồng nghĩa bác bỏ câu trả lời.
A4: Mã | B4: Nhóm nghiệp vụ | C4: Ưu tiên | D4: Câu hỏi cần chốt | E4: Phương án gợi ý / cách điền | F4: Lựa chọn (điền) | G4: Quyết định/Thông số cụ thể (điền) | H4: Trạng thái (điền) | I4: Đơn vị xác nhận đề xuất | J4: Người xác nhận (điền) | K4: Ngày chốt (điền) | L4: Ghi chú bổ sung (điền) | M4: Căn cứ / nguồn | N4: ĐÁNH GIÁ RÀ SOÁT | O4: LƯU Ý / CẦN XÁC NHẬN
A5: V01 | B5: 01. Vé xe / cổng | C5: P0 | D5: Đầu kéo vào KHÔNG có container (vé vào 0đ), sau đó kéo container ra: có thu thêm 250.000đ ở lượt ra không? | E5: A. Không, giữ giá tại cổng vào; B. Có, bổ sung phí khi ra có kéo cont; C. Chính sách khác. | F5: A | H5: Đã chốt | I5: Ban quản lý Sơn Cảng | M5: PRICE_LIST + luồng xe nhận container | N5: Đủ rõ để đặc tả | O5: Có lựa chọn được người dùng đánh dấu đã chốt; giữ nguyên câu trả lời và ghi chú.
A6: V02 | B6: 01. Vé xe / cổng | C6: P0 | D6: Vé vào có bắt buộc thu ngay trước khi cho xe qua cổng vào, hay được phép ghi Chưa thu để bổ sung sau? | E6: A. Bắt buộc thu đủ; B. Cho ghi Chưa thu có điều kiện; C. Chỉ ngoại lệ cần phê duyệt. | F6: A | G6: Nhưng cũng có trường họp thu sau(ít) | H6: Đã chốt | I6: Trưởng BP An ninh + CCKB | M6: Trao đổi nghiệp vụ Sơn Cảng, 10-11/10/2026 | N6: Cần làm rõ | O6: Thu vé ngay là mặc định, nhưng ghi chú cho phép thu sau (ít). Cần xác định ai cho phép và cách báo Chưa thu.
A7: V03 | B7: 01. Vé xe / cổng | C7: P0 | D7: Xe container KHÔNG lạnh/container khô hiện có được tiếp nhận không? Nếu có mã xe và đơn giá vé nào? | E7: A. Dùng CONT_LANH nếu chung 250.000đ; B. Tạo mã giá xe container khác; C. Không sử dụng loại này. | F7: Khác | G7: Chỉ có xe cont(250K) và xe đầu kéo k còn(0Đ) | H7: Đã chốt | I7: Trưởng BP An ninh | M7: Trao đổi nghiệp vụ Sơn Cảng, 10-11/10/2026 | N7: Cần làm rõ | O7: Người dùng dùng tên “xe cont” chung; PRICE_LIST hiện ghi CONT_LANH. Cần rà nhãn hiển thị, không đổi mã giá đã chốt.
A8: V04 | B8: 01. Vé xe / cổng | C8: P1 | D8: Xe bo ba bánh không có biển số được phân biệt lượt bằng mã vé; có cần thêm tên lái xe/đặc điểm xe/ảnh xe không? | E8: A. Chỉ mã vé tự sinh; B. Thêm thông tin nhận diện; C. Có thể nhập biển số khi có. | F8: A | G8: chỉ sinh cũng được nhưng đến lúc ra cũng chịu à, hoặc có thể sinh mã r điền vào vé thôi | H8: Đã chốt | I8: Trưởng BP An ninh | M8: Trao đổi nghiệp vụ Sơn Cảng, 10-11/10/2026 | N8: Cần làm rõ | O8: Không có biển số; người dùng lo không biết đối chiếu khi ra. Cần quy trình mã vé/tìm lượt.
A9: V05 | B9: 01. Vé xe / cổng | C9: P0 | D9: Vé giấy 2 liên có cần nhập/kiểm soát SỐ VÉ GIẤY bắt buộc khi ghi nhận xe vào không? | E9: A. Bắt buộc; B. Khuyến khích, không bắt buộc; C. Chuyển sang in/QR từ PWA. | F9: B | G9: sau này sẽ in | H9: Đã chốt | I9: Trưởng BP An ninh | M9: Trao đổi nghiệp vụ Sơn Cảng, 10-11/10/2026 | N9: Cần làm rõ | O9: Số vé giấy hiện không bắt buộc; người dùng nói “sau này sẽ in”. Cần xác định thuộc giai đoạn nào.
A10: V06 | B10: 01. Vé xe / cổng | C10: P0 | D10: Mất liên 02, phạt 250.000đ: bộ phận nào xác nhận, thu tiền và đánh dấu đã xử lý? | E10: A. An ninh nhận phạt; B. CCKB thu; C. An ninh xác nhận mất, CCKB thu; ghi rõ ngoại lệ. | F10: A | H10: Đã chốt | I10: Trưởng BP An ninh + CCKB | M10: Thông báo vé giấy Sơn Cảng | N10: Đủ rõ để đặc tả | O10: Có lựa chọn được người dùng đánh dấu đã chốt; giữ nguyên câu trả lời và ghi chú.
A11: V07 | B11: 01. Vé xe / cổng | C11: P1 | D11: Trường hợp khách có vé nhưng số vé/biển số không khớp: cho sửa vé tại cổng hay báo Trưởng BP xử lý? | E11: A. Chặn và yêu cầu phê duyệt; B. Cho xác minh bằng chứng từ; C. Quy trình khác. | F11: A | H11: Đã chốt | I11: Trưởng BP An ninh | M11: Trao đổi nghiệp vụ Sơn Cảng, 10-11/10/2026 | N11: Đủ rõ để đặc tả | O11: Có lựa chọn được người dùng đánh dấu đã chốt; giữ nguyên câu trả lời và ghi chú.
A12: V08 | B12: 01. Vé xe / cổng | C12: P1 | D12: Xe sang tải (tạp), đầu kéo 0đ có cần ghi nhận phiếu/vé giấy và xác nhận trạng thái Miễn phí hay không? | E12: A. Có kiểm soát đủ; B. Chỉ ghi lượt; C. Trường hợp khác. | F12: A | H12: Đã chốt | I12: Trưởng BP An ninh | M12: Trao đổi nghiệp vụ Sơn Cảng, 10-11/10/2026 | N12: Đủ rõ để đặc tả | O12: Có lựa chọn được người dùng đánh dấu đã chốt; giữ nguyên câu trả lời và ghi chú.
A13: V09 | B13: 01. Vé xe / cổng | C13: P1 | D13: Khi xe vào có kéo container, được phép nhập số container tạm/chưa rõ chính xác hay luôn bắt buộc số hợp lệ? | E13: A. Bắt buộc mã chính xác; B. Cho tạo tạm có phê duyệt; C. Được sửa trong thời hạn. | F13: A | H13: Đã chốt | I13: Trưởng BP An ninh + Điều phối | M13: Trao đổi nghiệp vụ Sơn Cảng, 10-11/10/2026 | N13: Cần làm rõ | O13: Chọn số container chính xác khi vào, nhưng nghiệp vụ thực tế thường nhập nhầm; cần cơ chế sửa có lịch sử và đối chiếu.
A14: V10 | B14: 01. Vé xe / cổng | C14: P0 | D14: Một lượt xe có thể chở trên 01 container cùng lúc không, đặc biệt với xe nhỏ hoặc phương tiện đặc biệt? | E14: A. Chỉ 01; B. Cho nhiều container; C. Tùy loại xe. | F14: A | H14: Đã chốt | I14: Trưởng BP An ninh + Điều phối | M14: Trao đổi nghiệp vụ Sơn Cảng, 10-11/10/2026 | N14: Đủ rõ để đặc tả | O14: Có lựa chọn được người dùng đánh dấu đã chốt; giữ nguyên câu trả lời và ghi chú.
A15: V11 | B15: 01. Vé xe / cổng | C15: P1 | D15: Khi xe ra không kéo container (đã hạ), có yêu cầu xác nhận riêng tại cổng hay chỉ chọn phương án ra không cont? | E15: A. Bắt buộc xác nhận; B. Theo trạng thái cont thực tế; C. Quy trình khác. | F15: A | H15: Đã chốt | I15: Trưởng BP An ninh | M15: Trao đổi nghiệp vụ Sơn Cảng, 10-11/10/2026 | N15: Đủ rõ để đặc tả | O15: Có lựa chọn được người dùng đánh dấu đã chốt; giữ nguyên câu trả lời và ghi chú.
A16: V12 | B16: 01. Vé xe / cổng | C16: P1 | D16: Sửa GIO_VAO/GIO_RA, biển số hoặc loại xe: ai được sửa, giới hạn thời gian và cần bằng chứng gì? | E16: A. Nhân viên sửa trước ra; B. TBP duyệt khi đã ra; C. Mọi sửa phải TBP duyệt. | F16: C | G16: cho phép sửa linh hoạt nhưng có log | H16: Đã chốt | I16: Trưởng BP An ninh | M16: Trao đổi nghiệp vụ Sơn Cảng, 10-11/10/2026 | N16: Cần làm rõ | O16: F=C (mọi sửa qua TBP) nhưng G=cho sửa linh hoạt, có log; cần chốt quyền riêng trước và sau khi xe đã ra.
A17: L01 | B17: 02. Lưu container | C17: P0 | D17: Nếu container vào trước 22:00 và ra đúng 22:00, có ghi nhận 1 đêm hay chưa? | E17: A. Tính 1 đêm (>=22:00); B. Chưa tính nếu ra đúng 22:00; C. Theo công thức AppSheet V1 đã nghiệm thu. | F17: A | H17: Đã chốt | I17: Trưởng BP CCKB | M17: Thông báo 22:00–06:00 | N17: Đủ rõ để đặc tả | O17: Có lựa chọn được người dùng đánh dấu đã chốt; giữ nguyên câu trả lời và ghi chú.
A18: L02 | B18: 02. Lưu container | C18: P0 | D18: Nếu container vào đúng 06:00 hoặc ra đúng 06:00, quy tắc gán cho kỳ đêm nào? | E18: A. Kỳ đêm kết thúc tại 06:00, ra 06:00 có tính; B. Kết thúc trước 06:00 mới tính; C. Theo V1. | F18: A | H18: Đã chốt | I18: Trưởng BP CCKB | M18: Trao đổi nghiệp vụ Sơn Cảng, 10-11/10/2026 | N18: Đủ rõ để đặc tả | O18: Có lựa chọn được người dùng đánh dấu đã chốt; giữ nguyên câu trả lời và ghi chú.
A19: L03 | B19: 02. Lưu container | C19: P0 | D19: Xe vào sau 22:00 (ví dụ 23:30) và ra trước 06:00 (02:00), đêm đó vẫn là 1 đêm miễn phí đúng không? | E19: A. Đúng; B. Chỉ khi qua mốc 06:00; C. Khác. | F19: A | H19: Đã chốt | I19: Trưởng BP CCKB | M19: Trao đổi nghiệp vụ Sơn Cảng, 10-11/10/2026 | N19: Đủ rõ để đặc tả | O19: Có lựa chọn được người dùng đánh dấu đã chốt; giữ nguyên câu trả lời và ghi chú.
A20: L04 | B20: 02. Lưu container | C20: P0 | D20: CCKB đã duyệt thanh toán trước 22:00, nhưng container thực tế xuất sau 22:00 và phát sinh thêm kỳ đêm: quy trình cập nhật phí? | E20: A. Hủy hiệu lực xác nhận cũ, tính và thu thêm; B. Khóa phí tại giờ CCKB duyệt; C. Trường hợp ngoại lệ riêng. | F20: B | G20: Vì nhiều lúc thanh toán và rút rồi nhưng chưa ra nhé | H20: Đã chốt | I20: Trưởng BP CCKB + An ninh | M20: Trao đổi nghiệp vụ Sơn Cảng, 10-11/10/2026 | N20: Cần làm rõ | O20: F=B khóa phí tại giờ CCKB duyệt; T09 lại chọn tính lại tại lúc cont thực ra. Cần xác định mốc chốt phí sau 22:00.
A21: L05 | B21: 02. Lưu container | C21: P1 | D21: Container vào ra trong cùng ngày, chưa qua 22:00: SO_DEM_LUU hiển thị 0 hay tối thiểu 1 (miễn phí)? | E21: A. Hiển thị 0; B. Hiển thị 1 (miễn); C. Tách đêm thực tế / đêm tính tiền. | F21: B | H21: Đã chốt | I21: Trưởng BP CCKB | M21: Trao đổi nghiệp vụ Sơn Cảng, 10-11/10/2026 | N21: Đủ rõ để đặc tả | O21: Có lựa chọn được người dùng đánh dấu đã chốt; giữ nguyên câu trả lời và ghi chú.
A22: L06 | B22: 02. Lưu container | C22: P1 | D22: Ai được sửa GIO_CONT_VAO/GIO_CONT_RA khi nhập muộn hoặc phát hiện sai? Việc sửa đã thu cần xử lý ra sao? | E22: A. Nhân viên đề xuất/TBP duyệt sau thu; B. TBP tự sửa có lý do; C. Quy trình khác. | F22: A | G22: A và B luôn | H22: Đã chốt | I22: Trưởng BP CCKB + An ninh | M22: Trao đổi nghiệp vụ Sơn Cảng, 10-11/10/2026 | N22: Cần làm rõ | O22: G=A và B: NV đề xuất/TBP duyệt hoặc TBP sửa trực tiếp; cần tách quyền theo trạng thái đã thu/chưa thu.
A23: L07 | B23: 02. Lưu container | C23: P0 | D23: Xe gốc đã ra nhưng container còn lại: CCKB duyệt tài chính cho lượt xe ra không kéo cont như thế nào? | E23: A. Chỉ cần vé xe; B. Cần xác nhận container tiếp tục ở bãi; C. Cần thêm xác nhận riêng. | F23: Khác | G23: duyệt theo container CCKB k quan tâ tới biểu số xe chỉ số cont | H23: Đã chốt | I23: Trưởng BP CCKB + An ninh | M23: Trao đổi nghiệp vụ Sơn Cảng, 10-11/10/2026 | N23: Đủ rõ để đặc tả | O23: Có lựa chọn được người dùng đánh dấu đã chốt; giữ nguyên câu trả lời và ghi chú.
A24: L08 | B24: 02. Lưu container | C24: P1 | D24: Nếu khách muốn trả trước một phần phí lưu container trong khi cont còn ở bãi, có cho phép ghi nhận không? | E24: A. Không; B. Có thanh toán trước, đối trừ khi ra; C. Chỉ nếu TBP duyệt. | F24: A | H24: Đã chốt | I24: Trưởng BP CCKB | M24: Trao đổi nghiệp vụ Sơn Cảng, 10-11/10/2026 | N24: Đủ rõ để đặc tả | O24: Có lựa chọn được người dùng đánh dấu đã chốt; giữ nguyên câu trả lời và ghi chú.
A25: L09 | B25: 02. Lưu container | C25: P1 | D25: Đơn giá phí lưu khi thay PRICE_LIST trong thời gian một container đang lưu: giữ giá lúc vào hay áp dụng theo từng kỳ ngày? | E25: A. Chốt tại GIO_CONT_VAO; B. Mỗi kỳ đêm theo bảng giá hiệu lực; C. Điều chỉnh bằng quyết định cụ thể. | F25: B | G25: Cái này khó nhỉ? A và B đi cho linh hoạt | H25: Đã chốt | I25: Trưởng BP CCKB + Quản trị | M25: Trao đổi nghiệp vụ Sơn Cảng, 10-11/10/2026 | N25: Cần làm rõ | O25: F=B tính giá theo từng đêm nhưng G muốn cả A và B linh hoạt; cần chính sách mặc định và ngoại lệ theo quyền.
A26: L10 | B26: 02. Lưu container | C26: P1 | D26: Có cần tính phí lưu cho container chưa xác định HÀNG/RỖNG, hay phải chờ Điều phối xác nhận? | E26: A. Vẫn tính; B. Chặn thanh toán đến khi rõ trạng thái; C. Khác. | F26: A | G26: Vẫn tính, có thể phân quyền lại cho user nào đó đi đếm nhé k nhất thiết điều phôi | H26: Đã chốt | I26: Trưởng BP CCKB + Điều phối | M26: Trao đổi nghiệp vụ Sơn Cảng, 10-11/10/2026 | N26: Đủ rõ để đặc tả | O26: Có lựa chọn được người dùng đánh dấu đã chốt; giữ nguyên câu trả lời và ghi chú.
A27: E01 | B27: 03. Cắm/rút điện | C27: P0 | D27: CCKB được tạo phiên cắm/rút và nhập giờ sau khi An ninh báo qua Zalo mà KHÔNG lập trước lệnh trong PWA chứ? | E27: A. Có, được nhập hồi tố và ghi giờ báo; B. Luôn phải lập yêu cầu trước; C. Kết hợp cả hai. | F27: C | G27: Cả 2 đi cho thoải mái | H27: Đã chốt | I27: Trưởng BP CCKB + An ninh | M27: Trao đổi nghiệp vụ Sơn Cảng, 10-11/10/2026 | N27: Đủ rõ để đặc tả | O27: Có lựa chọn được người dùng đánh dấu đã chốt; giữ nguyên câu trả lời và ghi chú.
A28: E02 | B28: 03. Cắm/rút điện | C28: P0 | D28: Trường hợp khách yêu cầu cắm/rút trực tiếp với An ninh mà chưa báo CCKB: xử lý nhập và xác minh ra sao? | E28: A. An ninh báo CCKB, nhập sau; B. Không làm khi chưa có CCKB; C. Ngoại lệ theo ca. | F28: Khác | G28: A và B | H28: Đã chốt | I28: Trưởng BP CCKB + An ninh | M28: Trao đổi nghiệp vụ Sơn Cảng, 10-11/10/2026 | N28: Cần làm rõ | O28: G=A và B: yêu cầu khách đi thẳng tới An ninh, vừa cho làm trước vừa muốn chờ CCKB; cần luồng ngoại lệ rõ.
A29: E03 | B29: 03. Cắm/rút điện | C29: P1 | D29: Hình thức Theo giờ và Cắm liên tục có khác nhau ở cách vận hành/thanh toán hay hiện chỉ khác danh mục yêu cầu? | E29: A. Chỉ khác tên; B. Có quy tắc riêng, ghi cụ thể; C. Sẽ phân biệt ở giai đoạn sau. | F29: A | G29: CHỉ khác là 1 cái biết giờ rút 1 cái chưa | H29: Đã chốt | I29: Trưởng BP CCKB | M29: Trao đổi nghiệp vụ Sơn Cảng, 10-11/10/2026 | N29: Cần làm rõ | O29: G xác định theo giờ biết giờ rút dự kiến, liên tục chưa biết; trước đó form không yêu cầu giờ rút dự kiến. Cần là trường tùy chọn.
A30: E04 | B30: 03. Cắm/rút điện | C30: P0 | D30: CCKB nhập GIO_CAM_THUC_TE khi container đã rút rồi: cho phép nhập cả giờ cắm và rút trong một biểu mẫu không? | E30: A. Có; B. Tách thành hai bước bắt buộc; C. Chỉ TBP nhập hồi tố. | F30: A | G30: có cho thoải mái giờ chưa kiểm soát chặt lắm | H30: Đã chốt | I30: Trưởng BP CCKB | M30: Trao đổi nghiệp vụ Sơn Cảng, 10-11/10/2026 | N30: Đủ rõ để đặc tả | O30: Có lựa chọn được người dùng đánh dấu đã chốt; giữ nguyên câu trả lời và ghi chú.
A31: E05 | B31: 03. Cắm/rút điện | C31: P0 | D31: Khi An ninh báo giờ cắm/rút không chính xác, CCKB xác minh bằng cách nào trước khi sửa? | E31: A. CCKB chỉnh có ghi chú; B. Cần ảnh tin nhắn Zalo; C. Phải có TBP xác nhận khi chênh lệch lớn. | F31: Khác | G31: Hienj tại khi cắm rút thì an ninh sẽ quay bằng camera time stamp, rồi gửi nhóm | H31: Đã chốt | I31: Trưởng BP CCKB | M31: Trao đổi nghiệp vụ Sơn Cảng, 10-11/10/2026 | N31: Đủ rõ để đặc tả | O31: Có lựa chọn được người dùng đánh dấu đã chốt; giữ nguyên câu trả lời và ghi chú.
A32: E06 | B32: 03. Cắm/rút điện | C32: P0 | D32: Sau khi đã thu tiền điện, CCKB được sửa giờ tới mức nào và quy trình phê duyệt chênh lệch? | E32: A. NV tạo đề nghị/TBP CCKB duyệt; B. TBP sửa trực tiếp có nhật ký; C. NV được sửa và ghi lý do (không duyệt). | F32: B | G32: A Và B | H32: Đã chốt | I32: Trưởng BP CCKB | M32: Đồng thuận sơ bộ: cần phê duyệt điều chỉnh sau thu | N32: Cần làm rõ | O32: F=B nhưng G=A và B: vừa NV đề nghị/TBP duyệt vừa TBP sửa trực tiếp; cần điều kiện khi nào mỗi cách.
A33: E07 | B33: 03. Cắm/rút điện | C33: P0 | D33: Phiên điện còn trạng thái Đang cắm trên PWA nhưng thực tế đã rút, container có được xuất không? | E33: A. CCKB bắt buộc hoàn thành ghi nhận trước khi ra; B. TBP duyệt xuất ngoại lệ; C. Khác. | F33: A | G33: Làm cách nào thoai r mái hon, CCKB cứ xác định xe đã được ra thì ra, nếu xe ra đến cổng mà chưa thấy được ra thì gọi hoặc nhắn nhóm có CCKB | H33: Đã chốt | I33: Trưởng BP CCKB + An ninh | M33: Trao đổi nghiệp vụ Sơn Cảng, 10-11/10/2026 | N33: Cần làm rõ | O33: F=A buộc cập nhật xong trước ra, nhưng G ưu tiên CCKB xác nhận bằng tay và Zalo khi cần; cần cơ chế override có audit.
A34: E08 | B34: 03. Cắm/rút điện | C34: P1 | D34: Khi không có mạng/không thể cập nhật giờ rút, cần quy trình bàn giao ngoài hệ thống và bổ sung dữ liệu như thế nào? | E34: A. Nhật ký giấy/Zalo rồi nhập lại có giờ nguồn; B. Không cho xuất cho đến khi hệ thống hoạt động; C. Ngoại lệ TBP. | F34: A | G34: chỗ này chưa hiểu | H34: Đã chốt | I34: Trưởng BP CCKB + Quản trị | M34: Trao đổi nghiệp vụ Sơn Cảng, 10-11/10/2026 | N34: Cần làm rõ | O34: G ghi “chỗ này chưa hiểu”; không thể coi là quyết định đã chốt dù F=A. Cần giải thích quy trình offline và nhập bù.
A35: E09 | B35: 03. Cắm/rút điện | C35: P1 | D35: Tổng thời gian thực tế tính bằng giây hay phút? Ví dụ 4 giờ 00 phút 01 giây có làm tròn thành 4 giờ 15 phút không? | E35: A. Bỏ giây/lấy phút; B. Giữ giây rồi làm tròn block 15 phút; C. Khác. | F35: Khác | G35: Hieện tại CCKB tự làm tròn | H35: Đã chốt | I35: Trưởng BP CCKB | M35: Trao đổi nghiệp vụ Sơn Cảng, 10-11/10/2026 | N35: Cần làm rõ | O35: G: CCKB tự làm tròn, trong khi đã chốt tính tròn lên mỗi 15 phút. Cần xác nhận tự tính mặc định + cho điều chỉnh thủ công.
A36: E10 | B36: 03. Cắm/rút điện | C36: P1 | D36: Phiên cắm ngắn dưới 15 phút hoặc vô tình cắm 0 phút: tính tối thiểu 15 phút khi có cắm thực tế không? | E36: A. >0 phút tính 15 phút; B. Có mức tối thiểu khác; C. Không thu dưới ngưỡng. | F36: Khác | G36: Hieện tại CCKB tự làm tròn | H36: Đã chốt | I36: Trưởng BP CCKB | M36: Trao đổi nghiệp vụ Sơn Cảng, 10-11/10/2026 | N36: Cần làm rõ | O36: G: CCKB tự làm tròn; chưa khóa khoản phí tối thiểu cho phiên ngắn dưới 15 phút và 0 phút.
A37: E11 | B37: 03. Cắm/rút điện | C37: P1 | D37: Một container cắm/rút nhiều phiên trong cùng một lần vào bãi: làm tròn 15 phút riêng mỗi phiên hay gộp trước khi làm tròn? | E37: A. Riêng từng phiên; B. Gộp thời gian nhiều phiên; C. Theo hình thức dịch vụ. | F37: A | H37: Đã chốt | I37: Trưởng BP CCKB | M37: Trao đổi nghiệp vụ Sơn Cảng, 10-11/10/2026 | N37: Đủ rõ để đặc tả | O37: Có lựa chọn được người dùng đánh dấu đã chốt; giữ nguyên câu trả lời và ghi chú.
A38: E12 | B38: 03. Cắm/rút điện | C38: P1 | D38: Có cho một container ghi nhận hai phiên cắm điện đồng thời hay bắt buộc mỗi thời điểm chỉ có một phiên? | E38: A. Chỉ một phiên hoạt động; B. Có nhiều ổ cắm/điểm cấp điện song song; C. Ngoại lệ. | F38: A | H38: Đã chốt | I38: Trưởng BP CCKB | M38: Trao đổi nghiệp vụ Sơn Cảng, 10-11/10/2026 | N38: Đủ rõ để đặc tả | O38: Có lựa chọn được người dùng đánh dấu đã chốt; giữ nguyên câu trả lời và ghi chú.
A39: E13 | B39: 03. Cắm/rút điện | C39: P1 | D39: Khi cập nhật giá điện trong lúc phiên cắm đang chạy: giữ giá lúc bắt đầu hay áp giá mới khi rút? | E39: A. Giữ giá lúc cắm; B. Theo giá lúc rút; C. Chia theo thời điểm đổi giá. | F39: B | G39: tùy A và B | H39: Đã chốt | I39: Trưởng BP CCKB + Quản trị | M39: Trao đổi nghiệp vụ Sơn Cảng, 10-11/10/2026 | N39: Cần làm rõ | O39: F=B tính giá mới khi rút, nhưng G “tùy A và B”; cần chính sách mặc định theo phiên và lựa chọn điều chỉnh giá.
A40: E14 | B40: 03. Cắm/rút điện | C40: P1 | D40: Có yêu cầu lưu vị trí/ổ cắm/số công tơ/ảnh khi cắm, hay chỉ theo container và giờ thực tế? | E40: A. Chỉ cont và giờ; B. Thêm vị trí ổ cắm; C. Thêm ảnh/công tơ; ghi rõ. | F40: A | G40: có thể cho an ninh điền cái này cx được để họ nhớ, sau này làm sơ đồ cũng dễ | H40: Đã chốt | I40: Trưởng BP CCKB + An ninh | M40: Trao đổi nghiệp vụ Sơn Cảng, 10-11/10/2026 | N40: Đủ rõ để đặc tả | O40: Có lựa chọn được người dùng đánh dấu đã chốt; giữ nguyên câu trả lời và ghi chú.
A41: E15 | B41: 03. Cắm/rút điện | C41: P1 | D41: Ai là người được phép sửa danh mục đơn giá cắm điện và có cần TBP/BLĐ phê duyệt mức giá mới? | E41: A. Quản trị; B. Trưởng BP CCKB; C. CCKB đề xuất, Quản trị duyệt; khác. | F41: A | H41: Đã chốt | I41: Trưởng BP CCKB + Quản trị | M41: Trao đổi nghiệp vụ Sơn Cảng, 10-11/10/2026 | N41: Đủ rõ để đặc tả | O41: Có lựa chọn được người dùng đánh dấu đã chốt; giữ nguyên câu trả lời và ghi chú.
...

Sheet 02_DA_CHOT
A1: QUYẾT ĐỊNH ĐÃ XÁC NHẬN — BAO GỒM PHẢN HỒI V1
A2: Các mục còn cần điều kiện chi tiết được ghi rõ trong cột Quy tắc; không suy diễn là hoàn thành mọi phân quyền và ngoại lệ.
A4: STT | B4: Nhóm | C4: Quyết định đã xác nhận | D4: Giá trị / Quy tắc | E4: Trách nhiệm | F4: Trạng thái | G4: Nguồn xác nhận
A5: 1 | B5: Phạm vi | C5: PWA/Web thay thế AppSheet Sơn Cảng sau nghiệm thu | D5: V1 có kiểm soát cổng, container, phí và cắm điện | E5: CNTT / Các BP | F5: Đã chốt | G5: Trao đổi do Sơn Cảng xác nhận, tháng 10/2026
A6: 2 | B6: Phạm vi | C6: Xây phân hệ cắm điện container ngay trong V1 | D6: Dùng chung dữ liệu container và cơ chế thanh toán | E6: CCKB / An ninh | F6: Đã chốt | G6: Trao đổi do Sơn Cảng xác nhận, tháng 10/2026
A7: 3 | B7: Nghiệp vụ | C7: Xe/container quản lý tách lượt, có thể khác xe vào/xe ra | D7: Xe hạ container rồi ra; container tiếp tục ở trong bãi | E7: An ninh / Điều phối | F7: Đã chốt | G7: Trao đổi do Sơn Cảng xác nhận, tháng 10/2026
A8: 4 | B8: Nghiệp vụ | C8: Xe có container có thể ra cùng container hoặc hạ container | D8: Việc hạ không quyết định phát sinh phí lưu | E8: An ninh | F8: Đã chốt | G8: Trao đổi do Sơn Cảng xác nhận, tháng 10/2026
A9: 5 | B9: Thông tin xe | C9: Xe có mang container mới yêu cầu nhập SO_CONTAINER | D9: Loại xe bo không mang container không bị hỏi số container | E9: An ninh | F9: Đã chốt | G9: Trao đổi do Sơn Cảng xác nhận, tháng 10/2026
A10: 6 | B10: Thông tin xe | C10: Xe bo ba bánh không yêu cầu biển số xe | D10: Phí vé vào 40.000 đồng/lượt | E10: An ninh | F10: Đã chốt | G10: Trao đổi do Sơn Cảng xác nhận, tháng 10/2026
A11: 7 | B11: Vé xe | C11: Xe container lạnh vé vào 250.000 đồng/lượt | D11: Dùng mã CONT_LANH trong PRICE_LIST | E11: An ninh | F11: Đã chốt | G11: Trao đổi do Sơn Cảng xác nhận, tháng 10/2026
A12: 8 | B12: Vé xe | C12: Đầu kéo không container vé vào 0 đồng/lượt | D12: Dùng mã DAU_KEO trong PRICE_LIST mới | E12: An ninh | F12: Đã chốt | G12: Trao đổi do Sơn Cảng xác nhận, tháng 10/2026
A13: 9 | B13: Vé xe | C13: Xe bo 3 chân / 4 chân vé vào 200.000 đồng/lượt | D13: Dùng mã riêng theo PRICE_LIST | E13: An ninh | F13: Đã chốt | G13: Trao đổi do Sơn Cảng xác nhận, tháng 10/2026
A14: 10 | B14: Vé xe | C14: Xe bo 8 tấn/2 chân vé vào 100.000 đồng/lượt | D14: Dùng mã XE_BO_8_TAN_2_CHAN | E14: An ninh | F14: Đã chốt | G14: Trao đổi do Sơn Cảng xác nhận, tháng 10/2026
A15: 11 | B15: Vé xe | C15: Xe sang tải (tạp) vé vào 0 đồng/lượt | D15: Dùng mã XE_SANG_TAI | E15: An ninh | F15: Đã chốt | G15: Trao đổi do Sơn Cảng xác nhận, tháng 10/2026
A16: 12 | B16: Lưu container | C16: Phí lưu tính theo CONTAINER, không phải lưu XE | D16: Bắt đầu GIO_CONT_VAO, kết thúc GIO_CONT_RA | E16: CCKB | F16: Đã chốt | G16: Trao đổi do Sơn Cảng xác nhận, tháng 10/2026
... A55: 51 | B55: Hóa đơn | C55: Bước tiếp nhận vé cần lưu thông tin khách/lái xe phục vụ hóa đơn | D55: Yêu cầu công nợ/hóa đơn tích hợp Kế toán dự kiến triển khai giai đoạn sau | E55: An ninh + Kế toán | F55: Đã chốt phần nguyên tắc | G55: V1 đã trả lời: T12 (G)

Sheet 03_BANG_GIA
A1: BẢNG GIÁ HIỆN HÀNH VÀ DÒNG GIÁ BỔ SUNG
A2: Giữ nguyên 8 dòng PRICE_LIST do Sơn Cảng cung cấp; bổ sung 2 mã cắm điện và 1 mã phạt mất vé để chuẩn hóa, cần xác nhận mã mới.
A4: MA_LOAI | B4: TEN_LOAI | C4: DOI_TUONG | D4: LOAI_PHI | E4: DON_GIA (VND) | F4: DON_VI_TINH | G4: MOC_BAT_DAU | H4: MOC_KET_THUC | I4: SO_DEM_MIEN_PHI | J4: HOAT_DONG | K4: THU_TU | L4: GHI_CHU | M4: Nguồn | N4: Phê duyệt mã thêm | O4: Ghi chú cập nhật (điền)
A5: CONT_LANH | B5: Xe container lạnh | C5: Phương tiện | D5: Vé vào | E5: 250000 | F5: Lượt | I5: 0 | J5: TRUE | K5: 1 | L5: Thu vé khi xe vào có kéo container | M5: PRICE_LIST gốc | N5: Đã xác nhận
A6: DAU_KEO | B6: Đầu kéo không container | C6: Phương tiện | D6: Vé vào | E6: 0 | F6: Lượt | I6: 0 | J6: TRUE | K6: 2 | L6: Thu vé khi đầu kéo vào không có container | M6: PRICE_LIST gốc | N6: Đã xác nhận
A7: XE_BO_4_CHAN | B7: Xe bo 4 chân | C7: Phương tiện | D7: Vé vào | E7: 200000 | F7: Lượt | I7: 0 | J7: TRUE | K7: 3 | L7: Thu tiền vé khi xe vào | M7: PRICE_LIST gốc | N7: Đã xác nhận
A8: XE_BO_3_CHAN | B8: Xe bo 3 chân | C8: Phương tiện | D8: Vé vào | E8: 200000 | F8: Lượt | I8: 0 | J8: TRUE | K8: 4 | L8: Thu tiền vé khi xe vào | M8: PRICE_LIST gốc | N8: Đã xác nhận
A9: XE_BO_8_TAN_2_CHAN | B9: Xe bo 8 tấn/2 chân | C9: Phương tiện | D9: Vé vào | E9: 100000 | F9: Lượt | I9: 0 | J9: TRUE | K9: 5 | L9: Thu tiền vé khi xe vào | M9: PRICE_LIST gốc | N9: Đã xác nhận
A10: XE_BO_3_BANH | B10: Xe bo 3 bánh | C10: Phương tiện | D10: Vé vào | E10: 40000 | F10: Lượt | I10: 0 | J10: TRUE | K10: 6 | L10: Thu tiền vé khi xe vào; không yêu cầu biển số | M10: PRICE_LIST gốc | N10: Đã xác nhận
A11: XE_SANG_TAI | B11: Xe sang tải (tạp) | C11: Phương tiện | D11: Vé vào | E11: 0 | F11: Lượt | I11: 0 | J11: TRUE | K11: 7 | L11: Miễn phí, chỉ kiểm soát xe ra vào | M11: PRICE_LIST gốc | N11: Đã xác nhận
A12: LUU_CONTAINER | B12: Phí lưu container | C12: Container | D12: Lưu đêm | E12: 100000 | F12: Đêm | G12: 22:00 | H12: 06:00 | I12: 1 | J12: TRUE | K12: 8 | L12: Phí lưu bằng (số đêm trừ một) nhân 100.000; kể cả không hạ cont | M12: PRICE_LIST gốc + chốt sau | N12: Đã xác nhận
A13: DIEN_CONT_GIO | B13: Cắm điện theo giờ | C13: Container | D13: Cắm điện | E13: 100000 | F13: Giờ | I13: 0 | J13: TRUE | K13: 9 | L13: Làm tròn lên từng 15 phút; CCKB nhập giờ thực tế | M13: Bổ sung theo chốt mới | N13: Mã đề xuất cần duyệt
A14: DIEN_CONT_LIEN_TUC | B14: Cắm điện liên tục | C14: Container | D14: Cắm điện | E14: 100000 | F14: Giờ | I14: 0 | J14: TRUE | K14: 10 | L14: Làm tròn lên từng 15 phút; CCKB nhập giờ thực tế | M14: Bổ sung theo chốt mới | N14: Mã đề xuất cần duyệt
A15: PHAT_MAT_VE | B15: Phạt mất liên 02 vé xe | C15: Vé xe | D15: Phạt | E15: 250000 | F15: Trường hợp | I15: 0 | J15: TRUE | K15: 11 | L15: Mức tiền theo thông báo; người trực tiếp thu còn cần chốt | M15: Bổ sung từ thông báo | N15: Mã đề xuất cần duyệt

Sheet 17_DE_XUAT_PHAN_QUYEN
A1: MA TRẬN QUYỀN ĐỀ XUẤT — PWA SƠN CẢNG
A2: BẢN THẨM ĐỊNH: cột E–K là quyền khuyến nghị; mọi phần khác biệt được tô vàng. Tab 04_PHAN_QUYEN giữ nguyên câu trả lời của bạn.
A3: Ký hiệu quyền: Thực hiện = thao tác; Xem = xem trong phạm vi; Đề nghị = gửi yêu cầu; Phê duyệt = quyết định; Không = không truy cập. CHƯA PHẢI QUYỀN ĐÃ DUYỆT.
A4: Mã | B4: Nhóm | C4: Chức năng / thao tác | D4: Bộ phận trách nhiệm đã chốt | E4: NV An ninh | F4: TBP An ninh | G4: NV CCKB | H4: TBP CCKB | I4: NV Điều phối | J4: TBP Điều phối | K4: Quản trị | L4: Ghi chú cần xác nhận (điền) | M4: Trạng thái | N4: Đánh giá | O4: Giải pháp / điều kiện an toàn | P4: Thay đổi cột | Q4: Mức ưu tiên
A5: Q01 | B5: Cổng vào | C5: Tạo lượt xe vào và giờ vào | D5: An ninh | E5: Thực hiện | F5: Thực hiện | G5: Không | H5: Không | I5: Không | J5: Không | K5: Thực hiện | M5: Đã chốt | N5: Giữ nguyên đề xuất của bạn | O5: Giữ như bản bạn điền; vẫn phải triển khai RBAC phía server, không chỉ ẩn nút trên giao diện. | P5: Không đổi giá trị | Q5: P2
A6: Q02 | B6: Cổng vào | C6: Thu tiền vé vào, đính kèm ảnh chuyển khoản | D6: An ninh | E6: Thực hiện | F6: Thực hiện | G6: Không | H6: Không | I6: Không | J6: Không | K6: Thực hiện | M6: Đã chốt | N6: Giữ nguyên đề xuất của bạn | O6: Giữ như bản bạn điền; vẫn phải triển khai RBAC phía server, không chỉ ẩn nút trên giao diện. | P6: Không đổi giá trị | Q6: P2
A7: Q03 | B7: Cổng vào | C7: Sửa biển số / loại xe / GIO_VAO | D7: An ninh | E7: Thực hiện | F7: Thực hiện | G7: Xem | H7: Xem | I7: Xem | J7: Xem | K7: Thực hiện | M7: Tách thao tác / chờ duyệt | N7: Tách thao tác / chờ duyệt | O7: Tách sửa biển số, loại xe và GIO_VAO thành các quyền riêng. Trước khi xuất cho An ninh sửa có audit; sau khi đã thu/đã xuất phải kiểm tra ảnh hưởng phí và cho TBP xử lý. Không tự sửa chứng từ đã thu. | P7: Không đổi giá trị | Q7: P0
A8: Q04 | B8: Cổng vào | C8: Tạo/điều chỉnh số vé giấy | D8: Chưa triển khai V1 | E8: Không | F8: Không | G8: Không | H8: Không | I8: Không | J8: Không | K8: Không | M8: Đề xuất hoãn V1 | N8: Đề xuất hoãn V1 | O8: Bạn ghi hiện chưa dùng chỉnh số vé giấy; do đó tắt thao tác thay đổi số vé giấy ở V1. Nếu cần vẫn có thể nhập số vé tham chiếu tùy chọn, không cấp quyền sửa tùy ý. | P8: D, E, F, G, H, I, J, K | Q8: P2
A9: Q05 | B9: Container | C9: Tạo lượt container vào, ghi GIO_CONT_VAO | D9: An ninh | E9: Thực hiện | F9: Thực hiện | G9: Không | H9: Không | I9: Không | J9: Không | K9: Thực hiện | M9: Đã chốt | N9: Giữ nguyên đề xuất của bạn | O9: Giữ như bản bạn điền; vẫn phải triển khai RBAC phía server, không chỉ ẩn nút trên giao diện. | P9: Không đổi giá trị | Q9: P2
A10: Q06 | B10: Container | C10: Thay đổi số container sau khi lưu | D10: An ninh | E10: Thực hiện | F10: Thực hiện | G10: Xem | H10: Xem | I10: Xem | J10: Xem | K10: Thực hiện | L10: Đã xác nhận cấp quyền cho An ninh sửa số cont và báo CCKB. Các ngoại lệ đã thanh toán/đã xuất vẫn cần chốt. | M10: Giữ quyền, bổ sung điều kiện | N10: Giữ quyền, bổ sung điều kiện | O10: Giữ quyền sửa số cont cho An ninh như bạn chọn; bắt buộc ghi số trước/sau, lý do, người sửa, giờ sửa và tự gửi cảnh báo tới CCKB. Nếu đã thu thì giữ giao dịch cũ; thay đổi số cont không tự động thay tiền. | P10: Không đổi giá trị | Q10: P0
A11: Q07 | B11: Container | C11: Xác nhận hạ/xếp container (quản lý vị trí) | D11: An ninh | E11: Thực hiện | F11: Thực hiện | G11: Xem | H11: Xem | I11: Thực hiện | J11: Thực hiện | K11: Thực hiện | M11: Giữ quyền, bổ sung điều kiện | N11: Giữ quyền, bổ sung điều kiện | O11: Nghiệp vụ hạ/xếp/vị trí là thông tin vận hành, không phải điều kiện tính phí lưu. Nếu chưa áp dụng kiểm soát vị trí trong V1, ẩn phần vị trí; vẫn lưu trạng thái xe ra không container. | P11: Không đổi giá trị | Q11: P2
A12: Q08 | B12: Điều phối | C12: Cập nhật HÀNG/RỖNG | D12: Điều phối | E12: Xem | F12: Xem | G12: Xem | H12: Xem | I12: Thực hiện | J12: Thực hiện | K12: Thực hiện | M12: Đề xuất sửa quyền | N12: Đề xuất sửa quyền | O12: Chỉ Điều phối nhập HÀNG/RỖNG; An ninh xem để đối chiếu. Tránh 2 bộ phận cập nhật chéo làm mất nguồn dữ liệu chuẩn. | P12: E, F | Q12: P0
A13: Q09 | B13: Điều phối | C13: Sửa HÀNG/RỖNG sau khi đã ra | D13: Điều phối | E13: Xem | F13: Xem | G13: Xem | H13: Xem | I13: Đề nghị | J13: Phê duyệt | K13: Thực hiện | M13: Đề xuất sửa quyền | N13: Đề xuất sửa quyền | O13: Sau khi container đã xuất: NV Điều phối chỉ đề nghị sửa; TBP Điều phối/Quản trị duyệt, ghi nhật ký trước/sau. Nếu chỉ sửa chú thích không ảnh hưởng phí thì có thể đơn giản hóa. | P13: E, F, I, J | Q13: P1
A14: Q10 | B14: Cắm điện | C14: Tạo yêu cầu cắm/rút từ khách hàng | D14: CCKB | E14: Xem | F14: Xem | G14: Thực hiện | H14: Thực hiện | I14: Xem | J14: Xem | K14: Thực hiện | M14: Đã chốt | N14: Giữ nguyên đề xuất của bạn | O14: Giữ như bản bạn điền; vẫn phải triển khai RBAC phía server, không chỉ ẩn nút trên giao diện. | P14: Không đổi giá trị | Q14: P2
A15: Q11 | B15: Cắm điện | C15: Thực hiện cắm/rút điện tại hiện trường | D15: An ninh | E15: Thực hiện | F15: Thực hiện | G15: Xem | H15: Xem | I15: Xem | J15: Xem | K15: Thực hiện | M15: Đề xuất sửa quyền | N15: Đề xuất sửa quyền | O15: Thao tác cắm/rút PHYSICAL chỉ An ninh thực hiện. CCKB tiếp nhận thông báo qua Zalo, sau đó nhập giờ tại Q12/Q13. Không bắt buộc An ninh nhập giờ trên PWA. | P15: G, H | Q15: P0
A16: Q12 | B16: Cắm điện | C16: Nhập GIO_CAM_THUC_TE | D16: CCKB | E16: Xem | F16: Xem | G16: Thực hiện | H16: Thực hiện | I16: Xem | J16: Xem | K16: Thực hiện | M16: Đã chốt | N16: Giữ nguyên đề xuất của bạn | O16: Giữ như bản bạn điền; vẫn phải triển khai RBAC phía server, không chỉ ẩn nút trên giao diện. | P16: Không đổi giá trị | Q16: P2
A17: Q13 | B17: Cắm điện | C17: Nhập GIO_RUT_THUC_TE | D17: CCKB | E17: Xem | F17: Xem | G17: Thực hiện | H17: Thực hiện | I17: Xem | J17: Xem | K17: Thực hiện | M17: Đã chốt | N17: Giữ nguyên đề xuất của bạn | O17: Giữ như bản bạn điền; vẫn phải triển khai RBAC phía server, không chỉ ẩn nút trên giao diện. | P17: Không đổi giá trị | Q17: P2
A18: Q14 | B18: Cắm điện | C18: Sửa giờ cắm/rút trước khi thu | D18: CCKB | E18: Xem | F18: Xem | G18: Thực hiện | H18: Thực hiện | I18: Xem | J18: Xem | K18: Thực hiện | M18: Giữ quyền, bổ sung điều kiện | N18: Giữ quyền, bổ sung điều kiện | O18: CCKB sửa giờ cắm/rút trước thu, hệ thống tính lại từng phiên bằng CEILING(số phút/15)*15; bắt buộc audit khi đã lưu trước đó. | P18: Không đổi giá trị | Q18: P1
A19: Q15 | B19: Cắm điện | C19: Đề nghị sửa giờ sau khi đã thu | D19: CCKB | E19: Xem | F19: Xem | G19: Đề nghị | H19: Đề nghị | I19: Xem | J19: Xem | K19: Thực hiện | M19: Đề xuất sửa quyền | N19: Đề xuất sửa quyền | O19: Nhân viên/TBP CCKB đề nghị điều chỉnh sau thu; Trưởng BP có quyền phê duyệt theo Q16. Không ghi đè trực tiếp khoản đã thanh toán. | P19: G, H | Q19: P0
A20: Q16 | B20: Cắm điện | C20: Phê duyệt chênh lệch sau khi thu | D20: TBP CCKB / Quản trị | E20: Xem | F20: Xem | G20: Xem | H20: Phê duyệt | I20: Xem | J20: Xem | K20: Phê duyệt | M20: Đề xuất sửa quyền | N20: Đề xuất sửa quyền | O20: Chỉ TBP CCKB hoặc Quản trị phê duyệt chênh lệch sau đã thu; người vừa đề nghị KHÔNG tự duyệt. Nếu TBP tự chỉnh thì cần giải trình/audit. Bút toán chênh lệch/hoàn tiền giữ nguyên chứng từ gốc. | P20: D, G, H, K | Q20: P0
A21: Q17 | B21: Cắm điện | C21: Quản lý danh mục giá điện và ngày hiệu lực | D21: Quản trị | E21: Xem | F21: Xem | G21: Xem | H21: Xem | I21: Xem | J21: Xem | K21: Thực hiện | M21: Đã chốt | N21: Giữ nguyên đề xuất của bạn | O21: Giữ như bản bạn điền; vẫn phải triển khai RBAC phía server, không chỉ ẩn nút trên giao diện. | P21: Không đổi giá trị | Q21: P2
A22: Q18 | B22: Thanh toán | C22: Tính/thu phí lưu container | D22: An ninh | E22: Thực hiện | F22: Thực hiện | G22: Xem | H22: Xem | I22: Xem | J22: Xem | K22: Thực hiện | M22: Giữ quyền, bổ sung điều kiện | N22: Giữ quyền, bổ sung điều kiện | O22: An ninh thu PHÍ LƯU CONTAINER đúng lúc GIO_CONT_RA thực tế được xác nhận, không khóa phí trước 22:00. Nếu chưa thu, phải ghi rõ nợ/ngoại lệ và kiểm tra quyền cho ra. | P22: Không đổi giá trị | Q22: P0
... A34: Q30 | B34: Báo cáo | C34: Xuất Excel/báo cáo phục vụ kiểm toán | D34: Quản trị (toàn bộ) / TBP (bộ phận) | E34: Không | F34: Thực hiện | G34: Không | H34: Thực hiện | I34: Không | J34: Không | K34: Thực hiện | M34: Đề xuất sửa quyền | N34: Đề xuất sửa quyền | O34: Cho TBP An ninh/CCKB xuất báo cáo thuộc BP để bàn giao đối soát. Báo cáo kiểm toán toàn bộ dữ liệu chỉ Quản trị. | P34: D, F, H | Q34: P2
A35: Q31 | B35: Cắm điện dự kiến | C35: Tạo yêu cầu cắm điện cho cont chưa vào (một hoặc nhiều số) | D35: CCKB | E35: Xem | F35: Xem | G35: Thực hiện | H35: Thực hiện | I35: Xem | J35: Xem | K35: Thực hiện | L35: Đề xuất NV/TBP CCKB thực hiện; chưa chốt chi tiết vai trò. | M35: Đề xuất sửa quyền | N35: Đề xuất sửa quyền | O35: CCKB nhập yêu cầu cho từng cont trước khi cont đến; An ninh phải nhìn thấy yêu cầu chờ để nhận diện lúc vào. Chưa có cont visit thì không tính phí lưu. | P35: E, F, G, H, I, J | Q35: P0
A36: Q32 | B36: Cắm điện dự kiến | C36: Sửa hoặc hủy yêu cầu điện dự kiến khi khách đổi số cont | D36: CCKB | E36: Xem | F36: Xem | G36: Thực hiện | H36: Thực hiện | I36: Xem | J36: Xem | K36: Thực hiện | L36: Cần chốt quyền, lưu lịch sử và thông báo An ninh. | M36: Đề xuất sửa quyền | N36: Đề xuất sửa quyền | O36: CCKB sửa/hủy yêu cầu dự kiến khi KH báo nhầm; phải lưu lịch sử và gửi thông báo lại An ninh. Không xóa mất bằng chứng đã nhận từ khách. | P36: E, F, G, H, I, J | Q36: P0
A37: Q33 | B37: Cổng vào | C37: Xem cảnh báo danh sách cont có yêu cầu cắm điện dự kiến | D37: An ninh | E37: Xem | F37: Xem | G37: Xem | H37: Xem | I37: Không | J37: Không | K37: Thực hiện | L37: Đã chốt An ninh cần nhìn thấy khi nhập container. | M37: Đề xuất sửa quyền | N37: Đề xuất sửa quyền | O37: An ninh phải THẤY cảnh báo cont có yêu cầu cắm điện dự kiến khi nhập tại cổng. Không chờ Quản trị mới xem được. | P37: E, F, G, H, I, J | Q37: P0
A38: Q34 | B38: Cổng vào | C38: Xác nhận ghép số cont dự kiến với lượt cont vào thực tế | D38: An ninh + CCKB | E38: Thực hiện | F38: Thực hiện | G38: Thực hiện | H38: Thực hiện | I38: Xem | J38: Xem | K38: Thực hiện | L38: Quy tắc ghép tự động/thủ công chưa chốt. | M38: Đề xuất sửa quyền | N38: Đề xuất sửa quyền | O38: An ninh đối chiếu cont thực vào với danh sách dự kiến và xác nhận ghép; CCKB kiểm tra/chỉnh phiếu theo kết quả. Gợi ý 7 số cuối/gần giống chỉ hỗ trợ, KHÔNG tự ghép. | P38: E, F, G, H, I, J | Q38: P0
A39: Q35 | B39: Container | C39: Sửa số cont đã nhập sai và ghi nhận đã báo CCKB | D39: An ninh | E39: Thực hiện | F39: Thực hiện | G39: Xem | H39: Xem | I39: Xem | J39: Xem | K39: Thực hiện | L39: Đã chốt bộ phận; cần quy định khi đã thu tiền. | M39: Đề xuất sửa quyền | N39: Đề xuất sửa quyền | O39: Tương đồng Q06: giữ AN được sửa đúng cont tại hiện trường và bấm Đã báo CCKB; số cũ, số mới, ảnh/video nếu có, lý do và audit bắt buộc. Nên gộp chức năng với Q06 trong UI. | P39: E, F, G, H, I, J | Q39: P0
A40: Q36 | B40: Container | C40: Tiếp nhận cảnh báo sửa số cont, kiểm tra và cập nhật yêu cầu dự kiến | D40: CCKB | E40: Xem | F40: Xem | G40: Thực hiện | H40: Thực hiện | I40: Xem | J40: Xem | K40: Thực hiện | L40: Quy trình xác nhận và phương thức báo lại cần chốt. | M40: Đề xuất sửa quyền | N40: Đề xuất sửa quyền | O40: CCKB tiếp nhận cảnh báo AN sửa số cont và được cập nhật phiếu dự kiến; lưu trạng thái đã xem/đã xử lý. Không tạo thêm phiên mới ngoài ý muốn. | P40: E, F, G, H, I, J | Q40: P0
A41: Q37 | B41: Chứng cứ | C41: Đính kèm ảnh/video nhận diện sai số container | D41: An ninh / CCKB | E41: Thực hiện | F41: Thực hiện | G41: Thực hiện | H41: Thực hiện | I41: Xem | J41: Xem | K41: Thực hiện | L41: Cần chốt bắt buộc hay không, kích thước và lưu trữ. | M41: Đề xuất sửa quyền | N41: Đề xuất sửa quyền | O41: AN hoặc CCKB được đính kèm ảnh/video đối chiếu. Khuyến khích ảnh/video; khi không có phải có lý do, không chặn thao tác nếu nguồn thực tế không cho chụp. | P41: E, F, G, H, I, J | Q41: P0
A42: Q38 | B42: Ngoại lệ | C42: Đối soát chênh lệch tiền sau khi sửa số container đã thu/đã ra | D42: TBP CCKB / Quản trị | E42: Xem | F42: Xem | G42: Đề nghị | H42: Phê duyệt | I42: Xem | J42: Xem | K42: Phê duyệt | L42: Không được tự động đổi lịch sử khoản thu đã chốt. | M42: Đề xuất tách nghiệp vụ | N42: Đề xuất tách nghiệp vụ | O42: SỬA MÃ CONTAINER luôn theo Q06/Q35 (AN được sửa có nhật ký). Q38 chỉ dùng khi phải ĐIỀU CHỈNH TIỀN đã thu do sửa số; cần TBP CCKB/Quản trị duyệt giao dịch điều chỉnh, không thay khoản đã thu gốc. | P42: C, D, E, F, G, H, I, J, K | Q42: P0
A43: Q39 | B43: Đối soát | C43: Xem và xác nhận đã xử lý cảnh báo sai số cont/không ghép được yêu cầu dự kiến | D43: CCKB + An ninh | E43: Thực hiện | F43: Thực hiện | G43: Thực hiện | H43: Thực hiện | I43: Xem | J43: Xem | K43: Thực hiện | L43: Cần trạng thái giao việc và phản hồi đóng thông báo. | M43: Đề xuất sửa quyền | N43: Đề xuất sửa quyền | O43: An ninh ghi đã báo/chụp hiện trường; CCKB đánh dấu đã kiểm tra/đối soát và đóng cảnh báo; trạng thái riêng từng BP, ai hoàn tất thao tác của mình. | P43: E, F, G, H, I, J | Q43: P0

Sheet 18_KET_LUAN_RUI_RO
A1: KẾT LUẬN THẨM ĐỊNH — BẢN PHÂN QUYỀN BẠN ĐÃ ĐIỀN
A2: ĐÁNH GIÁ: Cơ cấu 3 bộ phận đúng; cần sửa những quyền đang nhầm người, những thao tác admin-only và quyền tài chính nhạy cảm trước khi dùng làm mã nguồn.
A3: Bản gốc ở 04_PHAN_QUYEN; quyền sửa đề xuất ở 17_DE_XUAT_PHAN_QUYEN. Chưa tự ý xác nhận thay người dùng.
A5: STT | B5: Mã liên quan | C5: Mức | D5: Nhận xét kiểm tra | E5: Rủi ro nếu giữ nguyên | F5: Hướng xử lý khuyến nghị | G5: Loại quyết định | H5: Trạng thái rà soát
A6: 1 | B6: Q31–Q39 | C6: P0 | D6: 9 chức năng mới chỉ có Quản trị được thao tác; NV/TBP An ninh và CCKB để trống. | E6: Nghiệp vụ điện dự kiến và báo sai số cont không hoạt động đúng thực tế. | F6: Giao quyền tạo/sửa phiếu dự kiến cho CCKB; AN xem cảnh báo, xác nhận ghép và sửa số cont; CCKB tiếp nhận cảnh báo; AN/CCKB đính kèm bằng chứng. | G6: BẮT BUỘC SỬA | H6: Đề xuất / chờ duyệt
A7: 2 | B7: Q08–Q09 | C7: P0 | D7: An ninh được sửa trạng thái HÀNG/RỖNG, kể cả khi cont đã ra. | E7: Không còn một bộ phận sở hữu dữ liệu chuẩn; khó điều tra sai trạng thái. | F7: Điều phối nhập và chịu trách nhiệm; An ninh/CCKB xem; sửa sau khi ra phải có TBP phê duyệt/audit. | G7: BẮT BUỘC SỬA | H7: Đề xuất / chờ duyệt
A8: 3 | B8: Q11, Q12–Q13 | C8: P0 | D8: CCKB được ghi “Thực hiện cắm/rút điện tại hiện trường”. | E8: Trộn người thực hiện thực tế với người nhập giờ vào ứng dụng. | F8: An ninh trực tiếp cắm/rút; CCKB chỉ ghi giờ và quản lý tiền theo thông tin An ninh báo. | G8: BẮT BUỘC SỬA | H8: Đề xuất / chờ duyệt
A9: 4 | B9: Q15–Q16 | C9: P0 | D9: Nhân viên CCKB vừa được đề nghị vừa được phê duyệt chênh lệch sau thu. | E9: Có thể tự sửa giảm tiền đã thu mà không có kiểm tra độc lập. | F9: NV CCKB gửi đề nghị; TBP CCKB/Quản trị phê duyệt. Giữ bút toán tiền gốc và ghi chênh lệch. | G9: BẮT BUỘC SỬA | H9: Đề xuất / chờ duyệt
A10: 5 | B10: Q03,Q06,Q35,Q38 | C10: P0 | D10: Sửa giờ vào/số cont vẫn quá rộng; Q38 chồng chéo quyền sửa số cont và chỉnh tiền. | E10: Tiền lưu, tiền điện, lịch sử container và giao dịch đã thu có thể sai. | F10: Giữ AN quyền sửa số cont có audit/báo CCKB. Khi chỉnh tiền đã thu, TBP CCKB duyệt riêng; tách quyền sửa giờ ra/vào sau khi thu. | G10: BẮT BUỘC SỬA | H10: Đề xuất / chờ duyệt
A11: 6 | B11: Q18,Q24–Q25 | C11: P0 | D11: CCKB duyệt tài chính trước, trong khi AN chỉ tính phí lưu khi ghi giờ cont ra thật. | E11: Xuất container khi chưa ghi nhận/thu phí lưu phát sinh ở cổng. | F11: CCKB duyệt tiền điện + cảnh báo nợ; AN nhập giờ ra thật, tính/thu lưu; hệ thống kiểm tra thu hoặc ngoại lệ rồi mới ghi nhận ra. | G11: CẦN ĐIỀU KIỆN | H11: Áp dụng quy trình hai bước
A12: 7 | B12: Q26 | C12: P1 | D12: NV CCKB có thể hủy duyệt ra không tách trước/sau khi đã thực tế xuất. | E12: Lịch sử duyệt ra và công nợ có thể mâu thuẫn trạng thái cổng. | F12: Trước khi AN xác nhận ra: NV đề nghị, TBP/Quản trị hủy; sau khi ra: chỉ lập nghiệp vụ điều chỉnh có lịch sử. | G12: NÊN SỬA | H12: Đề xuất / chờ duyệt
A13: 8 | B13: Q28–Q30 | C13: P1 | D13: TBP An ninh và CCKB không được xem nhật ký, báo cáo doanh thu và xuất báo cáo. | E13: Không chủ động giám sát ca, đối soát hoặc điều tra sai sót. | F13: Cấp quyền theo phạm vi bộ phận; nhân viên chỉ xem khoản của mình; Quản trị được xem toàn bộ. | G13: NÊN SỬA | H13: Đề xuất / chờ duyệt
A14: 9 | B14: Q21 | C14: P1 | D14: Chỉ Quản trị được đối soát chứng từ chuyển khoản; người trực thu không tham gia quy trình kiểm tra. | E14: Mất khả năng giám sát tiền thực nhận hằng ngày tại An ninh/CCKB. | F14: TBP mỗi bộ phận đối soát các khoản thuộc phạm vi, có thể kết nối Kế toán ở giai đoạn sau. | G14: NÊN SỬA | H14: Đề xuất / chờ duyệt
A15: 10 | B15: Q04 | C15: P2 | D15: Không gán quyền nào và ghi “không sử dụng chỉnh vé giấy”, nhưng trạng thái vẫn “Đã chốt”. | E15: Nhóm lập trình có thể hiểu vẫn phải xây thao tác chỉnh vé giấy ngay V1. | F15: Gắn nhãn “Không triển khai V1”; chỉ lưu số vé nếu thực tế có, chức năng in/QR sau. | G15: GHI RÕ PHẠM VI | H15: Đề xuất / chờ duyệt
A16: 11 | B16: 15_V4_DIEM_CAN_KIEM | C16: P1 | D16: 12 điểm rà soát V4 chưa được bạn điền kết luận. | E16: Một số quy tắc kỹ thuật quan trọng vẫn là đề xuất. | F16: Ưu tiên RV03 giá điện đổi giữa phiên, RV05 điện đang cắm nhưng thực tế rút, RV06 phí lưu chưa thu, RV09 tài khoản chung bốt. | G16: CHƯA ĐỦ UAT | H16: Mở trong giai đoạn thiết kế
A17: 12 | B17: 14_V4_KICH_BAN | C17: P1 | D17: 44 kịch bản UAT vẫn ghi Chưa kiểm thử, chưa có kết quả chạy thực tế. | E17: Chưa có chứng cứ kiểm thử PWA hoặc nghiệm thu thay AppSheet. | F17: Sau khi có bản demo, chạy các kịch bản P0 trước; hiện chỉ có bảng yêu cầu và phân quyền. | G17: CHƯA ĐỦ UAT | H17: Để lúc có phần mềm

Sheet 04_PHAN_QUYEN
A1: MA TRẬN QUYỀN THEO 07 VAI TRÒ — CẦN XÁC NHẬN
A2: Các cột quyền đang để trống vì đã chốt TRÁCH NHIỆM BỘ PHẬN nhưng chưa chốt từng quyền. Chọn Thực hiện / Xem / Phê duyệt / Không.
A4: Mã | B4: Nhóm | C4: Chức năng / thao tác | D4: Bộ phận trách nhiệm đã chốt | E4: NV An ninh | F4: TBP An ninh | G4: NV CCKB | H4: TBP CCKB | I4: NV Điều phối | J4: TBP Điều phối | K4: Quản trị | L4: Ghi chú cần xác nhận (điền) | M4: Trạng thái
A5: Q01 | B5: Cổng vào | C5: Tạo lượt xe vào và giờ vào | D5: An ninh | E5: Thực hiện | F5: Thực hiện | G5: Không | H5: Không | I5: Không | J5: Không | K5: Thực hiện | M5: Đã chốt
A6: Q02 | B6: Cổng vào | C6: Thu tiền vé vào, đính kèm ảnh chuyển khoản | D6: An ninh | E6: Thực hiện | F6: Thực hiện | G6: Không | H6: Không | I6: Không | J6: Không | K6: Thực hiện | M6: Đã chốt
A7: Q03 | B7: Cổng vào | C7: Sửa biển số / loại xe / GIO_VAO | D7: An ninh | E7: Thực hiện | F7: Thực hiện | G7: Xem | H7: Xem | I7: Xem | J7: Xem | K7: Thực hiện | M7: Đã chốt
A8: Q04 | B8: Cổng vào | C8: Tạo/điều chỉnh số vé giấy | D8: An ninh | M8: Đã chốt | N8: k sử dụng điều chỉnh vé giấy mjes
A9: Q05 | B9: Container | C9: Tạo lượt container vào, ghi GIO_CONT_VAO | D9: An ninh | E9: Thực hiện | F9: Thực hiện | G9: Không | H9: Không | I9: Không | J9: Không | K9: Thực hiện | M9: Đã chốt
A10: Q06 | B10: Container | C10: Thay đổi số container sau khi lưu | D10: An ninh | E10: Thực hiện | F10: Thực hiện | G10: Xem | H10: Xem | I10: Xem | J10: Xem | K10: Thực hiện | L10: Đã xác nhận cấp quyền cho An ninh sửa số cont và báo CCKB. Các ngoại lệ đã thanh toán/đã xuất vẫn cần chốt. | M10: Đã chốt
A11: Q07 | B11: Container | C11: Xác nhận hạ/xếp container (quản lý vị trí) | D11: An ninh | E11: Thực hiện | F11: Thực hiện | G11: Xem | H11: Xem | I11: Thực hiện | J11: Thực hiện | K11: Thực hiện | M11: Đã chốt
A12: Q08 | B12: Điều phối | C12: Cập nhật HÀNG/RỖNG | D12: Điều phối | E12: Thực hiện | F12: Thực hiện | G12: Xem | H12: Xem | I12: Thực hiện | J12: Thực hiện | K12: Thực hiện | M12: Đã chốt
A13: Q09 | B13: Điều phối | C13: Sửa HÀNG/RỖNG sau khi đã ra | D13: Điều phối | E13: Thực hiện | F13: Thực hiện | G13: Xem | H13: Xem | I13: Thực hiện | J13: Thực hiện | K13: Thực hiện | M13: Đã chốt
A14: Q10 | B14: Cắm điện | C14: Tạo yêu cầu cắm/rút từ khách hàng | D14: CCKB | E14: Xem | F14: Xem | G14: Thực hiện | H14: Thực hiện | I14: Xem | J14: Xem | K14: Thực hiện | M14: Đã chốt
A15: Q11 | B15: Cắm điện | C15: Thực hiện cắm/rút điện tại hiện trường | D15: An ninh | E15: Thực hiện | F15: Thực hiện | G15: Thực hiện | H15: Thực hiện | I15: Xem | J15: Xem | K15: Thực hiện | M15: Đã chốt
A16: Q12 | B16: Cắm điện | C16: Nhập GIO_CAM_THUC_TE | D16: CCKB | E16: Xem | F16: Xem | G16: Thực hiện | H16: Thực hiện | I16: Xem | J16: Xem | K16: Thực hiện | M16: Đã chốt
A17: Q13 | B17: Cắm điện | C17: Nhập GIO_RUT_THUC_TE | D17: CCKB | E17: Xem | F17: Xem | G17: Thực hiện | H17: Thực hiện | I17: Xem | J17: Xem | K17: Thực hiện | M17: Đã chốt
A18: Q14 | B18: Cắm điện | C18: Sửa giờ cắm/rút trước khi thu | D18: CCKB | E18: Xem | F18: Xem | G18: Thực hiện | H18: Thực hiện | I18: Xem | J18: Xem | K18: Thực hiện | M18: Đã chốt
A19: Q15 | B19: Cắm điện | C19: Đề nghị sửa giờ sau khi đã thu | D19: CCKB | E19: Xem | F19: Xem | G19: Thực hiện | H19: Thực hiện | I19: Xem | J19: Xem | K19: Thực hiện | M19: Đã chốt
A20: Q16 | B20: Cắm điện | C20: Phê duyệt chênh lệch sau khi thu | D20: Quản trị | E20: Xem | F20: Xem | G20: Thực hiện | H20: Thực hiện | I20: Xem | J20: Xem | K20: Thực hiện | M20: Đã chốt
A21: Q17 | B21: Cắm điện | C21: Quản lý danh mục giá điện và ngày hiệu lực | D21: Quản trị | E21: Xem | F21: Xem | G21: Xem | H21: Xem | I21: Xem | J21: Xem | K21: Thực hiện | M21: Đã chốt
A22: Q18 | B22: Thanh toán | C22: Tính/thu phí lưu container | D22: An ninh | E22: Thực hiện | F22: Thực hiện | G22: Xem | H22: Xem | I22: Xem | J22: Xem | K22: Thực hiện | M22: Đã chốt
... A34: Q30 | B34: Báo cáo | C34: Xuất Excel/báo cáo phục vụ kiểm toán | D34: Chờ phân quyền | E34: Không | F34: Không | G34: Không | H34: Không | I34: Không | J34: Không | K34: Thực hiện | M34: Đã chốt
A35: Q31 | B35: Cắm điện dự kiến | C35: Tạo yêu cầu cắm điện cho cont chưa vào (một hoặc nhiều số) | D35: CCKB | K35: Thực hiện | L35: Đề xuất NV/TBP CCKB thực hiện; chưa chốt chi tiết vai trò. | M35: Đã chốt
A36: Q32 | B36: Cắm điện dự kiến | C36: Sửa hoặc hủy yêu cầu điện dự kiến khi khách đổi số cont | D36: CCKB | K36: Thực hiện | L36: Cần chốt quyền, lưu lịch sử và thông báo An ninh. | M36: Đã chốt
A37: Q33 | B37: Cổng vào | C37: Xem cảnh báo danh sách cont có yêu cầu cắm điện dự kiến | D37: An ninh | K37: Thực hiện | L37: Đã chốt An ninh cần nhìn thấy khi nhập container. | M37: Đã chốt
A38: Q34 | B38: Cổng vào | C38: Xác nhận ghép số cont dự kiến với lượt cont vào thực tế | D38: An ninh + CCKB | K38: Thực hiện | L38: Quy tắc ghép tự động/thủ công chưa chốt. | M38: Đã chốt
A39: Q35 | B39: Container | C39: Sửa số cont đã nhập sai và ghi nhận đã báo CCKB | D39: An ninh | K39: Thực hiện | L39: Đã chốt bộ phận; cần quy định khi đã thu tiền. | M39: Đã chốt
A40: Q36 | B40: Container | C40: Tiếp nhận cảnh báo sửa số cont, kiểm tra và cập nhật yêu cầu dự kiến | D40: CCKB | K40: Thực hiện | L40: Quy trình xác nhận và phương thức báo lại cần chốt. | M40: Đã chốt
A41: Q37 | B41: Chứng cứ | C41: Đính kèm ảnh/video nhận diện sai số container | D41: An ninh / CCKB | K41: Thực hiện | L41: Cần chốt bắt buộc hay không, kích thước và lưu trữ. | M41: Đã chốt
A42: Q38 | B42: Ngoại lệ | C42: Duyệt sửa số cont sau thanh toán/đã ra và đối soát phí | D42: Chờ phân quyền | K42: Thực hiện | L42: Không được tự động đổi lịch sử khoản thu đã chốt. | M42: Đã chốt
A43: Q39 | B43: Đối soát | C43: Xem và xác nhận đã xử lý cảnh báo sai số cont/không ghép được yêu cầu dự kiến | D43: CCKB + An ninh | K43: Thực hiện | L43: Cần trạng thái giao việc và phản hồi đóng thông báo. | M43: Đã chốt

Sheet 05_KICH_BAN
A1: BỘ TÌNH HUỐNG ĐỂ XÁC NHẬN QUY TẮC VÀ NGHIỆM THU
A2: Kịch bản chưa được chốt được ghi rõ là “Cần xác nhận”; ô màu vàng để bộ phận điền kết quả chuẩn trước khi kiểm thử.
A4: Mã | B4: Phân hệ | C4: Tình huống nghiệp vụ | D4: Dữ liệu đầu vào minh họa | E4: Kỳ vọng hiện có / cần xác nhận | F4: Mức độ | G4: Kết quả chuẩn Sơn Cảng (điền) | H4: Tình trạng | I4: Ghi chú kiểm thử (điền)
A5: TC01 | B5: Vé | C5: Xe container lạnh có cont vào bãi | D5: Loại CONT_LANH, có SO_CONTAINER | E5: Vé vào 250.000đ; An ninh thu | F5: P1 | H5: Có quy tắc
A6: TC02 | B6: Vé | C6: Đầu kéo vào không cont, ra không cont | D6: DAU_KEO | E6: Vé vào 0đ; không phí lưu cont | F6: P1 | H6: Có quy tắc
A7: TC03 | B7: Vé | C7: Đầu kéo vào không cont, ra kéo cont lưu trong bãi | D7: DAU_KEO + SO_CONTAINER_RA | E7: ĐÃ CHỐT V01: không thu thêm 250.000đ ở lượt ra; container vẫn được tính phí lưu theo lượt. | F7: P0 | H7: Có quy tắc
A8: TC04 | B8: Vé | C8: Xe bo ba bánh không có biển số | D8: XE_BO_3_BANH, BIEN_SO_XE rỗng | E8: Tạo mã lượt; tiền vé 40.000đ | F8: P1 | H8: Có quy tắc
A9: TC05 | B9: Vé | C9: Xe bo 3 chân vào không cont | D9: XE_BO_3_CHAN | E9: Vé vào 200.000đ; không phí lưu cont | F9: P1 | H9: Có quy tắc
A10: TC06 | B10: Vé | C10: Lái xe không xuất trình được liên 02 | D10: Vé đã phát, liên 02 mất | E10: Mức phạt 250.000đ; người xác nhận/thu CHƯA CHỐT | F10: P0 | H10: Chờ duyệt
A11: TC07 | B11: Lưu cont | C11: Cont ở trên xe, không hạ, ở qua 3 kỳ đêm | D11: 10/10 20:00 → 13/10 08:00 | E11: 3 đêm; miễn 1; thu 200.000đ | F11: P1 | H11: Có quy tắc
A12: TC08 | B12: Lưu cont | C12: Cont đã hạ, xe đầu vào ra một mình | D12: Xe A ra; cont còn trong bãi | E12: Cont vẫn tiếp tục tính phí đến GIO_CONT_RA | F12: P1 | H12: Có quy tắc
A13: TC09 | B13: Lưu cont | C13: Xe B đến kéo cont đã do xe A đưa vào | D13: ID_VEHICLE_VAO khác ID_VEHICLE_RA | E13: Phí tính cho cùng lượt cont, không khởi tạo lại GIO_CONT_VAO | F13: P1 | H13: Có quy tắc
A14: TC10 | B14: Lưu cont | C14: Cont vào và ra trong ngày, trước 22:00 | D14: 10/10 08:00 → 10/10 20:00 | E14: ĐÃ CHỐT L05=B: SO_DEM_LUU hiển thị tối thiểu 1 (miễn phí); tiền lưu 0đ. | F14: P0 | H14: Có quy tắc
A15: TC11 | B15: Lưu cont | C15: Ra đúng mốc 22:00 | D15: 10/10 20:00 → 10/10 22:00 | E15: ĐÃ CHỐT L01=A: ra đúng 22:00 ghi nhận một kỳ đêm (miễn đêm đầu). | F15: P0 | H15: Có quy tắc
A16: TC12 | B16: Lưu cont | C16: Ra đúng mốc 06:00 | D16: 10/10 23:00 → 11/10 06:00 | E16: ĐÃ CHỐT L02=A: ra đúng 06:00 vẫn tính thuộc kỳ đêm vừa kết thúc. | F16: P0 | H16: Có quy tắc
... A31: TC27 | B31: Mất mạng | C31: An ninh cho xe ra khi PWA offline | D31: Điện thoại không có internet | E31: ĐÃ CHỐT K03=A: offline cho phép ghi nhận chờ đồng bộ; không tự xác nhận ra cổng offline. | F31: P0 | H31: Có quy tắc
A32: TC28 | B32: Yêu cầu điện dự kiến | C32: CCKB tiếp nhận trước yêu cầu cắm A, B, C; chưa xe nào vào | D32: CCKB tạo yêu cầu cho A/B/C | E32: Đã chốt: ghi danh sách dự kiến; không tạo lượt cont vào và không tính tiền điện/lưu trước khi có sự kiện thực tế. | F32: P0 | H32: Có quy tắc | I32: Bổ sung nghiệp vụ mới ngày 11/10/2026
A33: TC29 | B33: Yêu cầu điện dự kiến | C33: Chỉ container A trong danh sách A,B,C đi vào cổng | D33: A vào trước, B/C chưa tới | E33: Đã chốt: An ninh thấy cảnh báo yêu cầu dự kiến. Đề xuất: chỉ A ghép lượt thực tế, B/C vẫn chờ. | F33: P0 | H33: Chờ duyệt | I33: Bổ sung nghiệp vụ mới ngày 11/10/2026
A34: TC30 | B34: Yêu cầu điện dự kiến | C34: An ninh gõ trùng số container trong yêu cầu dự kiến | D34: CCKB dự kiến ABCU1234567, thực tế ABCU1234567 | E34: Đã chốt: hiển thị yêu cầu dự kiến để đối chiếu. Cơ chế ghép tự động/chọn tay cần xác nhận PR04. | F34: P0 | H34: Chờ duyệt | I34: Bổ sung nghiệp vụ mới ngày 11/10/2026
A35: TC31 | B35: Đối chiếu số cont | C35: Số container khách báo trước sai 1 ký tự so với số thực tế | D35: ABCU1234567 vs ACBU1234567 | E35: Đề xuất: cảnh báo mã gần giống, không tự ghép/đổi số khi khác; An ninh xác minh thực tế. | F35: P0 | H35: Chờ duyệt | I35: Bổ sung nghiệp vụ mới ngày 11/10/2026
A36: TC32 | B36: Sửa số cont | C36: An ninh thấy số đã nhập nhầm sau khi chụp ảnh hiện trường | D36: Số dự kiến/nhập khác ảnh cont thực tế | E36: Đã chốt: An ninh có thể sửa và báo lại CCKB; đề xuất giữ giá trị cũ/mới, người sửa, lý do và chứng cứ. | F36: P0 | H36: Có quy tắc | I36: Bổ sung nghiệp vụ mới ngày 11/10/2026
A37: TC33 | B37: Sửa số cont | C37: Khách ban đầu báo sai số cont, CCKB nhập sai yêu cầu dự kiến | D37: Khách nhắn A, thực tế B | E37: Đề xuất: CCKB cập nhật yêu cầu dự kiến theo số thực tế; không tạo trùng lượt cont. | F37: P0 | H37: Chờ duyệt | I37: Bổ sung nghiệp vụ mới ngày 11/10/2026
A38: TC34 | B38: Liên kết điện | C38: Sau khi đã nhập giờ cắm, An ninh phát hiện video chụp cont khác số đã liên kết | D38: Phiên điện nối nhầm cont A thay vì B | E38: Đề xuất: quy trình sửa liên kết phiên điện có kiểm soát; audit, thông báo CCKB và tính lại liên quan. | F38: P0 | H38: Chờ duyệt | I38: Bổ sung nghiệp vụ mới ngày 11/10/2026
A39: TC35 | B39: Sau khi thu tiền | C39: Sửa số cont sau khi phí điện/lưu đã thu hoặc CCKB đã duyệt cho ra | D39: Trạng thái tiền đã thu/đã duyệt | E39: Đề xuất: không thay ngầm giao dịch tài chính; cần tái kiểm tra và xác nhận ngoại lệ. | F39: P0 | H39: Chờ duyệt | I39: Bổ sung nghiệp vụ mới ngày 11/10/2026
A40: TC36 | B40: Dữ liệu trùng | C40: Có hai yêu cầu dự kiến cùng số cont nhưng khác khách hàng hoặc 2 cont cùng mã đang trong bãi | D40: ABCU1234567 lặp trong hai yêu cầu | E40: Đề xuất: cảnh báo trùng và yêu cầu phân định đúng lượt thực tế; không tự nhập/thu trùng. | F40: P0 | H40: Chờ duyệt | I40: Bổ sung nghiệp vụ mới ngày 11/10/2026
A41: TC37 | B41: Yêu cầu điện dự kiến | C41: Container đã được đăng ký dự kiến nhưng khách hủy/không đến | D41: Dự kiến A/B/C, hủy C | E41: Đề xuất: cho hủy dòng C, giữ lịch sử; không thay dữ liệu A/B và không tạo phí. | F41: P1 | H41: Chờ duyệt | I41: Bổ sung nghiệp vụ mới ngày 11/10/2026
A42: TC38 | B42: Tình huống mạng | C42: An ninh tra cứu yêu cầu dự kiến nhưng mất Internet tại cổng | D42: PWA offline, cần xác nhận cont | E42: Cần chốt: thông báo dữ liệu có thể chưa cập nhật; không tự ghép hay xác nhận tài chính/cho ra khi offline. | F42: P0 | H42: Chờ duyệt | I42: Bổ sung nghiệp vụ mới ngày 11/10/2026
