Workbook

Sheet 00_TONG_QUAN
A1: BẢNG TỔNG HỢP YÊU CẦU PWA SƠN CẢNG — V3
A2: 11/10/2026 | Đã nhập nguyên văn phản hồi V1 đúng; bổ sung đăng ký cắm điện trước khi cont vào và chỉnh số cont.
A4: TIẾN ĐỘ XÁC NHẬN
A5: TỔNG CÂU HỎI | C5: ĐÃ CÓ LỰA CHỌN | E5: CẦN LÀM RÕ | G5: P0 CẦN XỬ LÝ | I5: ĐỦ RÕ ĐẶC TẢ
A6: =COUNTA('01_CAU_HOI'!$A$5:$A$250) | C6: =COUNTIF('01_CAU_HOI'!$F$5:$F$250,"<>") | E6: =COUNTIF('01_CAU_HOI'!$N$5:$N$250,"Cần làm rõ") | G6: =COUNTIFS('01_CAU_HOI'!$C$5:$C$250,"P0",'01_CAU_HOI'!$N$5:$N$250,"Cần làm rõ")+COUNTIFS('01_CAU_HOI'!$C$5:$C$250,"P0",'01_CAU_HOI'!$N$5:$N$250,"Chưa trả lời") | I6: =IFERROR(COUNTIF('01_CAU_HOI'!$N$5:$N$250,"Đủ rõ để đặc tả")/A6,0)
A8: CÁCH ĐIỀN FILE
A9: 1. Mở 01_CAU_HOI: F/G/H giữ NGUYÊN phản hồi V1 của bạn; không cần nhập lại.
A10: 2. Lọc N = Cần làm rõ/Chưa trả lời; hoặc vào 11_RA_SOAT_V1 để bổ sung quyết định và giải thích.
A11: 3. Những câu PR/SC liên quan container dự kiến, sai số cont đã được đưa từ V2 sang và vẫn giữ trạng thái đúng.
A12: 4. 02_DA_CHOT tổng hợp các nguyên tắc được xác nhận; 12_TRA_LOI_V1_GOC lưu nguyên các câu trả lời V1 để đối chiếu.
A13: 5. Tiếp tục rà soát giá/thu tiền/ngoại lệ cho ra; KHÔNG xem mọi ô H=Đã chốt là đặc tả đã đủ rõ.
A14: 6. Dùng 04_PHAN_QUYEN để gán quyền, 05_KICH_BAN để kiểm thử, 09_TINH_DIEN để thử tiền điện 15 phút.
A15: 7. Sử dụng các tab tham chiếu: giá, tài khoản, mapping, đối soát và quy trình dự kiến/sửa số cont.
A18: TỔNG HỢP THEO NHÓM
A19: Nhóm nghiệp vụ | D19: Tổng | F19: Đủ rõ | H19: Cần xử lý
A20: 01. Vé xe / cổng | D20: =COUNTIF('01_CAU_HOI'!$B$5:$B$250,A20) | F20: =COUNTIFS('01_CAU_HOI'!$B$5:$B$250,A20,'01_CAU_HOI'!$N$5:$N$250,"Đủ rõ để đặc tả") | H20: =COUNTIFS('01_CAU_HOI'!$B$5:$B$250,A20,'01_CAU_HOI'!$N$5:$N$250,"Cần làm rõ")+COUNTIFS('01_CAU_HOI'!$B$5:$B$250,A20,'01_CAU_HOI'!$N$5:$N$250,"Chưa trả lời")
A21: 02. Lưu container | D21: =COUNTIF('01_CAU_HOI'!$B$5:$B$250,A21) | F21: =COUNTIFS('01_CAU_HOI'!$B$5:$B$250,A21,'01_CAU_HOI'!$N$5:$N$250,"Đủ rõ để đặc tả") | H21: =COUNTIFS('01_CAU_HOI'!$B$5:$B$250,A21,'01_CAU_HOI'!$N$5:$N$250,"Cần làm rõ")+COUNTIFS('01_CAU_HOI'!$B$5:$B$250,A21,'01_CAU_HOI'!$N$5:$N$250,"Chưa trả lời")
A22: 03. Cắm/rút điện | D22: =COUNTIF('01_CAU_HOI'!$B$5:$B$250,A22) | F22: =COUNTIFS('01_CAU_HOI'!$B$5:$B$250,A22,'01_CAU_HOI'!$N$5:$N$250,"Đủ rõ để đặc tả") | H22: =COUNTIFS('01_CAU_HOI'!$B$5:$B$250,A22,'01_CAU_HOI'!$N$5:$N$250,"Cần làm rõ")+COUNTIFS('01_CAU_HOI'!$B$5:$B$250,A22,'01_CAU_HOI'!$N$5:$N$250,"Chưa trả lời")
A23: 04. Thanh toán | D23: =COUNTIF('01_CAU_HOI'!$B$5:$B$250,A23) | F23: =COUNTIFS('01_CAU_HOI'!$B$5:$B$250,A23,'01_CAU_HOI'!$N$5:$N$250,"Đủ rõ để đặc tả") | H23: =COUNTIFS('01_CAU_HOI'!$B$5:$B$250,A23,'01_CAU_HOI'!$N$5:$N$250,"Cần làm rõ")+COUNTIFS('01_CAU_HOI'!$B$5:$B$250,A23,'01_CAU_HOI'!$N$5:$N$250,"Chưa trả lời")
A24: 05. Phân quyền | D24: =COUNTIF('01_CAU_HOI'!$B$5:$B$250,A24) | F24: =COUNTIFS('01_CAU_HOI'!$B$5:$B$250,A24,'01_CAU_HOI'!$N$5:$N$250,"Đủ rõ để đặc tả") | H24: =COUNTIFS('01_CAU_HOI'!$B$5:$B$250,A24,'01_CAU_HOI'!$N$5:$N$250,"Cần làm rõ")+COUNTIFS('01_CAU_HOI'!$B$5:$B$250,A24,'01_CAU_HOI'!$N$5:$N$250,"Chưa trả lời")
A25: 06. Điều phối / container | D25: =COUNTIF('01_CAU_HOI'!$B$5:$B$250,A25) | F25: =COUNTIFS('01_CAU_HOI'!$B$5:$B$250,A25,'01_CAU_HOI'!$N$5:$N$250,"Đủ rõ để đặc tả") | H25: =COUNTIFS('01_CAU_HOI'!$B$5:$B$250,A25,'01_CAU_HOI'!$N$5:$N$250,"Cần làm rõ")+COUNTIFS('01_CAU_HOI'!$B$5:$B$250,A25,'01_CAU_HOI'!$N$5:$N$250,"Chưa trả lời")
A26: 07. Báo cáo / đối soát | D26: =COUNTIF('01_CAU_HOI'!$B$5:$B$250,A26) | F26: =COUNTIFS('01_CAU_HOI'!$B$5:$B$250,A26,'01_CAU_HOI'!$N$5:$N$250,"Đủ rõ để đặc tả") | H26: =COUNTIFS('01_CAU_HOI'!$B$5:$B$250,A26,'01_CAU_HOI'!$N$5:$N$250,"Cần làm rõ")+COUNTIFS('01_CAU_HOI'!$B$5:$B$250,A26,'01_CAU_HOI'!$N$5:$N$250,"Chưa trả lời")
A27: 08. Kỹ thuật / bảo mật | D27: =COUNTIF('01_CAU_HOI'!$B$5:$B$250,A27) | F27: =COUNTIFS('01_CAU_HOI'!$B$5:$B$250,A27,'01_CAU_HOI'!$N$5:$N$250,"Đủ rõ để đặc tả") | H27: =COUNTIFS('01_CAU_HOI'!$B$5:$B$250,A27,'01_CAU_HOI'!$N$5:$N$250,"Cần làm rõ")+COUNTIFS('01_CAU_HOI'!$B$5:$B$250,A27,'01_CAU_HOI'!$N$5:$N$250,"Chưa trả lời")
A28: 09. Chuyển dữ liệu | D28: =COUNTIF('01_CAU_HOI'!$B$5:$B$250,A28) | F28: =COUNTIFS('01_CAU_HOI'!$B$5:$B$250,A28,'01_CAU_HOI'!$N$5:$N$250,"Đủ rõ để đặc tả") | H28: =COUNTIFS('01_CAU_HOI'!$B$5:$B$250,A28,'01_CAU_HOI'!$N$5:$N$250,"Cần làm rõ")+COUNTIFS('01_CAU_HOI'!$B$5:$B$250,A28,'01_CAU_HOI'!$N$5:$N$250,"Chưa trả lời")
A29: 10. Nghiệm thu / triển khai | D29: =COUNTIF('01_CAU_HOI'!$B$5:$B$250,A29) | F29: =COUNTIFS('01_CAU_HOI'!$B$5:$B$250,A29,'01_CAU_HOI'!$N$5:$N$250,"Đủ rõ để đặc tả") | H29: =COUNTIFS('01_CAU_HOI'!$B$5:$B$250,A29,'01_CAU_HOI'!$N$5:$N$250,"Cần làm rõ")+COUNTIFS('01_CAU_HOI'!$B$5:$B$250,A29,'01_CAU_HOI'!$N$5:$N$250,"Chưa trả lời")
A32: LƯU Ý: 98 dòng V1 được giữ nguyên trạng thái người dùng tự đánh dấu; cột RÀ SOÁT mới là thước đo độ đủ rõ để lập trình.
A34: DỮ LIỆU GỐC: PRICE_LIST và USERS do Sơn Cảng cung cấp; VEHICLE 315 bản ghi, CONTAINER 259 bản ghi (tính từ các tệp đính kèm).
A35: BẢN V1 TRẢ LỜI ĐÚNG ĐÃ NHẬP: Untitled spreadsheet (1).xlsx | Không tự sửa dữ liệu gốc; mọi điểm xung đột được đánh dấu.
A36: Đi tới bảng CÂU HỎI | D36: Đi tới các quyết định ĐÃ CHỐT | G36: Đi tới MA TRẬN PHÂN QUYỀN
A38: Đi tới BẢNG GIÁ | D38: Đi tới TÌNH HUỐNG UAT | G38: Đi tới MÔ PHỎNG TIỀN ĐIỆN

Sheet 01_CAU_HOI
A1: BẢNG CÂU HỎI PWA SƠN CẢNG — ĐÃ HỢP NHẤT TRẢ LỜI V1
A2: Cột F/G/H: dữ liệu trả lời nguyên văn từ V1; cột N/O: kết quả rà soát của trợ lý. Cần làm rõ KHÔNG đồng nghĩa bác bỏ câu trả lời.
A4: Mã | B4: Nhóm nghiệp vụ | C4: Ưu tiên | D4: Câu hỏi cần chốt | E4: Phương án gợi ý / cách điền | F4: Lựa chọn (điền) | G4: Quyết định/Thông số cụ thể (điền) | H4: Trạng thái (điền) | I4: Đơn vị xác nhận đề xuất | J4: Người xác nhận (điền) | K4: Ngày chốt (điền) | L4: Ghi chú bổ sung (điền) | M4: Căn cứ / nguồn | N4: ĐÁNH GIÁ RÀ SOÁT | O4: LƯU Ý / CẦN XÁC NHẬN
A5: V01 | B5: 01. Vé xe / cổng | C5: P0 | D5: Đầu kéo vào KHÔNG có container (vé vào 0đ), sau đó kéo container ra: có thu thêm 250.000đ ở lượt ra không? | E5: A. Không, giữ giá tại cổng vào; B. Có, bổ sung phí khi ra có kéo cont; C. Chính sách khác. | F5: A | H5: Đã chốt | I5: Ban quản lý Sơn Cảng | M5: PRICE_LIST + luồng xe nhận container | N5: Đủ rõ để đặc tả | O5: Có lựa chọn được người dùng đánh dấu đã chốt; giữ nguyên câu trả lời và ghi chú.
A6: V02 | B6: 01. Vé xe / cổng | C6: P0 | D6: Vé vào có bắt buộc thu ngay trước khi cho xe qua cổng vào, hay được phép ghi Chưa thu để bổ sung sau? | E6: A. Bắt buộc thu đủ; B. Cho ghi Chưa thu có điều kiện; C. Chỉ ngoại lệ cần phê duyệt. | F6: A | G6: Nhưng cũng có trường họp thu sau(ít) | H6: Đã chốt | I6: Trưởng BP An ninh + CCKB | M6: Trao đổi nghiệp vụ Sơn Cảng, 10-11/10/2026 | N6: Cần làm rõ | O6: Thu vé ngay là mặc định, nhưng ghi chú cho phép thu sau (ít). Cần xác định ai cho phép và cách báo Chưa thu.
A7: V03 | B7: 01. Vé xe / cổng | C7: P0 | D7: Xe container KHÔNG lạnh/container khô hiện có được tiếp nhận không? Nếu có mã xe và đơn giá vé nào? | E7: A. Dùng CONT_LANH nếu chung 250.000đ; B. Tạo mã giá xe container khác; C. Không sử dụng loại này. | F7: Khác | G7: Chỉ có xe cont(250K) và xe đầu kéo k còn(0Đ) | H7: Đã chốt | I7: Trưởng BP An ninh | M7: Trao đổi nghiệp vụ Sơn Cảng, 10-11/10/2026 | N7: Cần làm rõ | O7: Người dùng dùng tên “xe cont” chung; PRICE_LIST hiện ghi CONT_LANH. Cần rà nhãn hiển thị, không đổi mã giá đã chốt.
A8: V04 | B8: 01. Vé xe / cổng | C8: P1 | D8: Xe bo ba bánh không có biển số được phân biệt lượt bằng mã vé; có cần thêm tên lái xe/đặc điểm xe/ảnh xe không? | E8: A. Chỉ mã vé tự sinh; B. Thêm thông tin nhận diện; C. Có thể nhập biển số khi có. | F8: A | G8: chỉ sinh cũng được nhưng đến lúc ra cũng chịu à, hoặc có thể sinh mã r điền vào vé thôi | H8: Đã chốt | I8: Trưởng BP An ninh | M8: Trao đổi nghiệp vụ Sơn Cảng, 10-11/10/2026 | N8: Cần làm rõ | O8: Không có biển số; người dùng lo không biết đối chiếu khi ra. Cần quy trình mã vé/tìm lượt.
A9: V05 | B9: 01. Vé xe / cổng | C9: P0 | D9: Vé giấy 2 liên có cần nhập/kiểm soát SỐ VÉ GIẤY bắt buộc khi ghi nhận xe vào không? | E9: A. Bắt buộc; B. Khuyến khích, không bắt buộc; C. Chuyển sang in/QR từ PWA. | F9: B | G9: sau này sẽ in | H9: Đã chốt | I9: Trưởng BP An ninh | M9: Trao đổi nghiệp vụ Sơn Cảng, 10-11/10/2026 | N9: Cần làm rõ | O9: Số vé giấy hiện không bắt buộc; người dùng nói “sau này sẽ in”. Cần xác định thuộc giai đoạn nào.
A10: V06 | B10: 01. Vé xe / cổng | C10: P0 | D10: Mất liên 02, phạt 250.000đ: bộ phận nào xác nhận, thu tiền và đánh dấu đã xử lý? | E10: A. An ninh nhận phạt; B. CCKB thu; C. An ninh xác nhận mất, CCKB thu; ghi rõ ngoại lệ. | F10: A | H10: Đã chốt | I10: Trưởng BP An ninh + CCKB | M10: Thông báo vé giấy Sơn Cảng | N10: Đủ rõ để đặc tả | O10: Có lựa chọn được người dùng đánh dấu đã chốt; giữ nguyên câu trả lời và ghi chú.
A11: V07 | B11: 01. Vé xe / cổng | C11: P1 | D11: Trường hợp khách có vé nhưng số vé/biển số không khớp: cho sửa vé tại cổng hay báo Trưởng BP xử lý? | E11: A. Chặn và yêu cầu phê duyệt; B. Cho xác minh bằng chứng từ; C. Quy trình khác. | F11: A | H11: Đã chốt | I11: Trưởng BP An ninh | M11: Trao đổi nghiệp vụ Sơn Cảng, 10-11/10/2026 | N11: Đủ rõ để đặc tả | O11: Có lựa chọn được người dùng đánh dấu đã chốt; giữ nguyên câu trả lời và ghi chú.
A12: V08 | B12: 01. Vé xe / cổng | C12: P1 | D12: Xe sang tải (tạp), đầu kéo 0đ có cần ghi nhận phiếu/vé giấy và xác nhận trạng thái Miễn phí hay không? | E12: A. Có kiểm soát đủ; B. Chỉ ghi lượt; C. Trường hợp khác. | F12: A | H12: Đã chốt | I12: Trưởng BP An ninh | M12: Trao đổi nghiệp vụ Sơn Cảng, 10-11/10/2026 | N12: Đủ rõ để đặc tả | O12: Có lựa chọn được người dùng đánh dấu đã chốt; giữ nguyên câu trả lời và ghi chú.
A13: V09 | B13: 01. Vé xe / cổng | C13: P1 | D13: Khi xe vào có kéo container, được phép nhập số container tạm/chưa rõ chính xác hay luôn bắt buộc số hợp lệ? | E13: A. Bắt buộc mã chính xác; B. Cho tạo tạm có phê duyệt; C. Được sửa trong thời hạn. | F13: A | H13: Đã chốt | I13: Trưởng BP An ninh + Điều phối | M13: Trao đổi nghiệp vụ Sơn Cảng, 10-11/10/2026 | N13: Cần làm rõ | O13: Chọn số container chính xác khi vào, nhưng nghiệp vụ thực tế thường nhập nhầm; cần cơ chế sửa có lịch sử và đối chiếu.
A14: V10 | B14: 01. Vé xe / cổng | C14: P0 | D14: Một lượt xe có thể chở trên 01 container cùng lúc không, đặc biệt với xe nhỏ hoặc phương tiện đặc biệt? | E14: A. Chỉ 01; B. Cho nhiều container; C. Tùy loại xe. | F14: A | H14: Đã chốt | I14: Trưởng BP An ninh + Điều phối | M14: Trao đổi nghiệp vụ Sơn Cảng, 10-11/10/2026 | N14: Đủ rõ để đặc tả | O14: Có lựa chọn được người dùng đánh dấu đã chốt; giữ nguyên câu trả lời và ghi chú.
A15: V11 | B15: 01. Vé xe / cổng | C15: P1 | D15: Khi xe ra không kéo container (đã hạ), có yêu cầu xác nhận riêng tại cổng hay chỉ chọn phương án ra không cont? | E15: A. Bắt buộc xác nhận; B. Theo trạng thái cont thực tế; C. Quy trình khác. | F15: A | H15: Đã chốt | I15: Trưởng BP An ninh | M15: Trao đổi nghiệp vụ Sơn Cảng, 10-11/10/2026 | N15: Đủ rõ để đặc tả | O15: Có lựa chọn được người dùng đánh dấu đã chốt; giữ nguyên câu trả lời và ghi chú.
A16: V12 | B16: 01. Vé xe / cổng | C16: P1 | D16: Sửa GIO_VAO/GIO_RA, biển số hoặc loại xe: ai được sửa, giới hạn thời gian và cần bằng chứng gì? | E16: A. Nhân viên sửa trước ra; B. TBP duyệt khi đã ra; C. Mọi sửa phải TBP duyệt. | F16: C | G16: cho phép sửa linh hoạt nhưng có log | H16: Đã chốt | I16: Trưởng BP An ninh | M16: Trao đổi nghiệp vụ Sơn Cảng, 10-11/10/2026 | N16: Cần làm rõ | O16: F=C (mọi sửa qua TBP) nhưng G=cho sửa linh hoạt, có log; cần chốt quyền riêng trước và sau khi xe đã ra.
A17: L01 | B17: 02. Lưu container | C17: P0 | D17: Nếu container vào trước 22:00 và ra đúng 22:00, có ghi nhận 1 đêm hay chưa? | E17: A. Tính 1 đêm (>=22:00); B. Chưa tính nếu ra đúng 22:00; C. Theo công thức AppSheet V1 đã nghiệm thu. | F17: A | H17: Đã chốt | I17: Trưởng BP CCKB | M17: Thông báo 22:00–06:00 | N17: Đủ rõ để đặc tả | O17: Có lựa chọn được người dùng đánh dấu đã chốt; giữ nguyên câu trả lời và ghi chú.
A18: L02 | B18: 02. Lưu container | C18: P0 | D18: Nếu container vào đúng 06:00 hoặc ra đúng 06:00, quy tắc gán cho kỳ đêm nào? | E18: A. Kỳ đêm kết thúc tại 06:00, ra 06:00 có tính; B. Kết thúc trước 06:00 mới tính; C. Theo V1. | F18: A | H18: Đã chốt | I18: Trưởng BP CCKB | M18: Trao đổi nghiệp vụ Sơn Cảng, 10-11/10/2026 | N18: Đủ rõ để đặc tả | O18: Có lựa chọn được người dùng đánh dấu đã chốt; giữ nguyên câu trả lời và ghi chú.
A19: L03 | B19: 02. Lưu container | C19: P0 | D19: Xe vào sau 22:00 (ví dụ 23:30) và ra trước 06:00 (02:00), đêm đó vẫn là 1 đêm miễn phí đúng không? | E19: A. Đúng; B. Chỉ khi qua mốc 06:00; C. Khác. | F19: A | H19: Đã chốt | I19: Trưởng BP CCKB | M19: Trao đổi nghiệp vụ Sơn Cảng, 10-11/10/2026 | N19: Đủ rõ để đặc tả | O19: Có lựa chọn được người dùng đánh dấu đã chốt; giữ nguyên câu trả lời và ghi chú.
A20: L04 | B20: 02. Lưu container | C20: P0 | D20: CCKB đã duyệt thanh toán trước 22:00, nhưng container thực tế xuất sau 22:00 và phát sinh thêm kỳ đêm: quy trình cập nhật phí? | E20: A. Hủy hiệu lực xác nhận cũ, tính và thu thêm; B. Khóa phí tại giờ CCKB duyệt; C. Trường hợp ngoại lệ riêng. | F20: B | G20: Vì nhiều lúc thanh toán và rút rồi nhưng chưa ra nhé | H20: Đã chốt | I20: Trưởng BP CCKB + An ninh | M20: Trao đổi nghiệp vụ Sơn Cảng, 10-11/10/2026 | N20: Cần làm rõ | O20: F=B khóa phí tại giờ CCKB duyệt; T09 lại chọn tính lại tại lúc cont thực ra. Cần xác định mốc chốt phí sau 22:00.
A21: L05 | B21: 02. Lưu container | C21: P1 | D21: Container vào ra trong cùng ngày, chưa qua 22:00: SO_DEM_LUU hiển thị 0 hay tối thiểu 1 (miễn phí)? | E21: A. Hiển thị 0; B. Hiển thị 1 (miễn); C. Tách đêm thực tế / đêm tính tiền. | F21: B | H21: Đã chốt | I21: Trưởng BP CCKB | M21: Trao đổi nghiệp vụ Sơn Cảng, 10-11/10/2026 | N21: Đủ rõ để đặc tả | O21: Có lựa chọn được người dùng đánh dấu đã chốt; giữ nguyên câu trả lời và ghi chú.
A22: L06 | B22: 02. Lưu container | C22: P1 | D22: Ai được sửa GIO_CONT_VAO/GIO_CONT_RA khi nhập muộn hoặc phát hiện sai? Việc sửa đã thu cần xử lý ra sao? | E22: A. Nhân viên đề xuất/TBP duyệt sau thu; B. TBP tự sửa có lý do; C. Quy trình khác. | F22: A | G22: A và B luôn | H22: Đã chốt | I22: Trưởng BP CCKB + An ninh | M22: Trao đổi nghiệp vụ Sơn Cảng, 10-11/10/2026 | N22: Cần làm rõ | O22: G=A và B: NV đề xuất/TBP duyệt hoặc TBP sửa trực tiếp; cần tách quyền theo trạng thái đã thu/chưa thu.
A23: L07 | B23: 02. Lưu container | C23: P0 | D23: Xe gốc đã ra nhưng container còn lại: CCKB duyệt tài chính cho lượt xe ra không kéo cont như thế nào? | E23: A. Chỉ cần vé xe; B. Cần xác nhận container tiếp tục ở bãi; C. Cần thêm xác nhận riêng. | F23: Khác | G23: duyệt theo container CCKB k quan tâ tới biểu số xe chỉ số cont | H23: Đã chốt | I23: Trưởng BP CCKB + An ninh | M23: Trao đổi nghiệp vụ Sơn Cảng, 10-11/10/2026 | N23: Đủ rõ để đặc tả | O23: Có lựa chọn được người dùng đánh dấu đã chốt; giữ nguyên câu trả lời và ghi chú.
A24: L08 | B24: 02. Lưu container | C24: P1 | D24: Nếu khách muốn trả trước một phần phí lưu container trong khi cont còn ở bãi, có cho phép ghi nhận không? | E24: A. Không; B. Có thanh toán trước, đối trừ khi ra; C. Chỉ nếu TBP duyệt. | F24: A | H24: Đã chốt | I24: Trưởng BP CCKB | M24: Trao đổi nghiệp vụ Sơn Cảng, 10-11/10/2026 | N24: Đủ rõ để đặc tả | O24: Có lựa chọn được người dùng đánh dấu đã chốt; giữ nguyên câu trả lời và ghi chú.
A25: L09 | B25: 02. Lưu container | C25: P1 | D25: Đơn giá phí lưu khi thay PRICE_LIST trong thời gian một container đang lưu: giữ giá lúc vào hay áp dụng theo từng kỳ ngày? | E25: A. Chốt tại GIO_CONT_VAO; B. Mỗi kỳ đêm theo bảng giá hiệu lực; C. Điều chỉnh bằng quyết định cụ thể. | F25: B | G25: Cái này khó nhỉ? A và B đi cho linh hoạt | H25: Đã chốt | I25: Trưởng BP CCKB + Quản trị | M25: Trao đổi nghiệp vụ Sơn Cảng, 10-11/10/2026 | N25: Cần làm rõ | O25: F=B tính giá theo từng đêm nhưng G muốn cả A và B linh hoạt; cần chính sách mặc định và ngoại lệ theo quyền.
A26: L10 | B26: 02. Lưu container | C26: P1 | D26: Có cần tính phí lưu cho container chưa xác định HÀNG/RỖNG, hay phải chờ Điều phối xác nhận? | E26: A. Vẫn tính; B. Chặn thanh toán đến khi rõ trạng thái; C. Khác. | F26: A | G26: Vẫn tính, có thể phân quyền lại cho user nào đó đi đếm nhé k nhất thiết điều phôi | H26: Đã chốt | I26: Trưởng BP CCKB + Điều phối | M26: Trao đổi nghiệp vụ Sơn Cảng, 10-11/10/2026 | N26: Đủ rõ để đặc tả | O26: Có lựa chọn được người dùng đánh dấu đã chốt; giữ nguyên câu trả lời và ghi chú.
A27: E01 | B27: 03. Cắm/rút điện | C27: P0 | D27: CCKB được tạo phiên cắm/rút và nhập giờ sau khi An ninh báo qua Zalo mà KHÔNG lập trước lệnh trong PWA chứ? | E27: A. Có, được nhập hồi tố và ghi giờ báo; B. Luôn phải lập yêu cầu trước; C. Kết hợp cả hai. | F27: C | G27: Cả 2 đi cho thoải mái | H27: Đã chốt | I27: Trưởng BP CCKB + An ninh | M27: Trao đổi nghiệp vụ Sơn Cảng, 10-11/10/2026 | N27: Đủ rõ để đặc tả | O27: Có lựa chọn được người dùng đánh dấu đã chốt; giữ nguyên câu trả lời và ghi chú.
A28: E02 | B28: 03. Cắm/rút điện | C28: P0 | D28: Trường hợp khách yêu cầu cắm/rút trực tiếp với An ninh mà chưa báo CCKB: xử lý nhập và xác minh ra sao? | E28: A. An ninh báo CCKB, nhập sau; B. Không làm khi chưa có CCKB; C. Ngoại lệ theo ca. | F28: Khác | G28: A và B | H28: Đã chốt | I28: Trưởng BP CCKB + An ninh | M28: Trao đổi nghiệp vụ Sơn Cảng, 10-11/10/2026 | N28: Cần làm rõ | O28: G=A và B: yêu cầu khách đi thẳng tới An ninh, vừa cho làm trước vừa muốn chờ CCKB; cần luồng ngoại lệ rõ.
A29: E03 | B29: 03. Cắm/rút điện | C29: P1 | D29: Hình thức Theo giờ và Cắm liên tục có khác nhau ở cách vận hành/thanh toán hay hiện chỉ khác danh mục yêu cầu? | E29: A. Chỉ khác tên; B. Có quy tắc riêng, ghi cụ thể; C. Sẽ phân biệt ở giai đoạn sau. | F29: A | G29: CHỉ khác là 1 cái biết giờ rút 1 cái chưa | H29: Đã chốt | I29: Trưởng BP CCKB | M29: Trao đổi nghiệp vụ Sơn Cảng, 10-11/10/2026 | N29: Cần làm rõ | O29: G xác định theo giờ biết giờ rút dự kiến, liên tục chưa biết; trước đó form không yêu cầu giờ rút dự kiến. Cần là trường tùy chọn.
A30: E04 | B30: 03. Cắm/rút điện | C30: P0 | D30: CCKB nhập GIO_CAM_THUC_TE khi container đã rút rồi: cho phép nhập cả giờ cắm và rút trong một biểu mẫu không? | E30: A. Có; B. Tách thành hai bước bắt buộc; C. Chỉ TBP nhập hồi tố. | F30: A | G30: có cho thoải mái giờ chưa kiểm soát chặt lắm | H30: Đã chốt | I30: Trưởng BP CCKB | M30: Trao đổi nghiệp vụ Sơn Cảng, 10-11/10/2026 | N30: Đủ rõ để đặc tả | O30: Có lựa chọn được người dùng đánh dấu đã chốt; giữ nguyên câu trả lời và ghi chú.
A31: E05 | B31: 03. Cắm/rút điện | C31: P0 | D31: Khi An ninh báo giờ cắm/rút không chính xác, CCKB xác minh bằng cách nào trước khi sửa? | E31: A. CCKB chỉnh có ghi chú; B. Cần ảnh tin nhắn Zalo; C. Phải có TBP xác nhận khi chênh lệch lớn. | F31: Khác | G31: Hienj tại khi cắm rút thì an ninh sẽ quay bằng camera time stamp, rồi gửi nhóm | H31: Đã chốt | I31: Trưởng BP CCKB | M31: Trao đổi nghiệp vụ Sơn Cảng, 10-11/10/2026 | N31: Đủ rõ để đặc tả | O31: Có lựa chọn được người dùng đánh dấu đã chốt; giữ nguyên câu trả lời và ghi chú.
A32: E06 | B32: 03. Cắm/rút điện | C32: P0 | D32: Sau khi đã thu tiền điện, CCKB được sửa giờ tới mức nào và quy trình phê duyệt chênh lệch? | E32: A. NV tạo đề nghị/TBP CCKB duyệt; B. TBP sửa trực tiếp có nhật ký; C. NV được sửa và ghi lý do (không duyệt). | F32: B | G32: A Và B | H32: Đã chốt | I32: Trưởng BP CCKB | M32: Đồng thuận sơ bộ: cần phê duyệt điều chỉnh sau thu | N32: Cần làm rõ | O32: F=B nhưng G=A và B: vừa NV đề nghị/TBP duyệt vừa TBP sửa trực tiếp; cần điều kiện khi nào mỗi cách.
A33: E07 | B33: 03. Cắm/rút điện | C33: P0 | D33: Phiên điện còn trạng thái Đang cắm trên PWA nhưng thực tế đã rút, container có được xuất không? | E33: A. CCKB bắt buộc hoàn thành ghi nhận trước khi ra; B. TBP duyệt xuất ngoại lệ; C. Khác. | F33: A | G33: Làm cách nào thoai r mái hon, CCKB cứ xác định xe đã được ra thì ra, nếu xe ra đến cổng mà chưa thấy được ra thì gọi hoặc nhắn nhóm có CCKB | H33: Đã chốt | I33: Trưởng BP CCKB + An ninh | M33: Trao đổi nghiệp vụ Sơn Cảng, 10-11/10/2026 | N33: Cần làm rõ | O33: F=A buộc cập nhật xong trước ra, nhưng G ưu tiên CCKB xác nhận bằng tay và Zalo khi cần; cần cơ chế override có audit.
A34: E08 | B34: 03. Cắm/rút điện | C34: P1 | D34: Khi không có mạng/không thể cập nhật giờ rút, cần quy trình bàn giao ngoài hệ thống và bổ sung dữ liệu như thế nào? | E34: A. Nhật ký giấy/Zalo rồi nhập lại có giờ nguồn; B. Không cho xuất cho đến khi hệ thống hoạt động; C. Ngoại lệ TBP. | F34: A | G34: chỗ này chưa hiểu | H34: Đã chốt | I34: Trưởng BP CCKB + Quản trị | M34: Trao đổi nghiệp vụ Sơn Cảng, 10-11/10/2026 | N34: Cần làm rõ | O34: G ghi “chỗ này chưa hiểu”; không thể coi là quyết định đã chốt dù F=A. Cần giải thích quy trình offline và nhập bù.
A35: E09 | B35: 03. Cắm/rút điện | C35: P1 | D35: Tổng thời gian thực tế tính bằng giây hay phút? Ví dụ 4 giờ 00 phút 01 giây có làm tròn thành 4 giờ 15 phút không? | E35: A. Bỏ giây/lấy phút; B. Giữ giây rồi làm tròn block 15 phút; C. Khác. | F35: Khác | G35: Hieện tại CCKB tự làm tròn | H35: Đã chốt | I35: Trưởng BP CCKB | M35: Trao đổi nghiệp vụ Sơn Cảng, 10-11/10/2026 | N35: Cần làm rõ | O35: G: CCKB tự làm tròn, trong khi đã chốt tính tròn lên mỗi 15 phút. Cần xác nhận tự tính mặc định + cho điều chỉnh thủ công.
A36: E10 | B36: 03. Cắm/rút điện | C36: P1 | D36: Phiên cắm ngắn dưới 15 phút hoặc vô tình cắm 0 phút: tính tối thiểu 15 phút khi có cắm thực tế không? | E36: A. >0 phút tính 15 phút; B. Có mức tối thiểu khác; C. Không thu dưới ngưỡng. | F36: Khác | G36: Hieện tại CCKB tự làm tròn | H36: Đã chốt | I36: Trưởng BP CCKB | M36: Trao đổi nghiệp vụ Sơn Cảng, 10-11/10/2026 | N36: Cần làm rõ | O36: G: CCKB tự làm tròn; chưa khóa khoản phí tối thiểu cho phiên ngắn dưới 15 phút và 0 phút.
A37: E11 | B37: 03. Cắm/rút điện | C37: P1 | D37: Một container cắm/rút nhiều phiên trong cùng một lần vào bãi: làm tròn 15 phút riêng mỗi phiên hay gộp trước khi làm tròn? | E37: A. Riêng từng phiên; B. Gộp thời gian nhiều phiên; C. Theo hình thức dịch vụ. | F37: A | H37: Đã chốt | I37: Trưởng BP CCKB | M37: Trao đổi nghiệp vụ Sơn Cảng, 10-11/10/2026 | N37: Đủ rõ để đặc tả | O37: Có lựa chọn được người dùng đánh dấu đã chốt; giữ nguyên câu trả lời và ghi chú.
A38: E12 | B38: 03. Cắm/rút điện | C38: P1 | D38: Có cho một container ghi nhận hai phiên cắm điện đồng thời hay bắt buộc mỗi thời điểm chỉ có một phiên? | E38: A. Chỉ một phiên hoạt động; B. Có nhiều ổ cắm/điểm cấp điện song song; C. Ngoại lệ. | F38: A | H38: Đã chốt | I38: Trưởng BP CCKB | M38: Trao đổi nghiệp vụ Sơn Cảng, 10-11/10/2026 | N38: Đủ rõ để đặc tả | O38: Có lựa chọn được người dùng đánh dấu đã chốt; giữ nguyên câu trả lời và ghi chú.
A39: E13 | B39: 03. Cắm/rút điện | C39: P1 | D39: Khi cập nhật giá điện trong lúc phiên cắm đang chạy: giữ giá lúc bắt đầu hay áp giá mới khi rút? | E39: A. Giữ giá lúc cắm; B. Theo giá lúc rút; C. Chia theo thời điểm đổi giá. | F39: B | G39: tùy A và B | H39: Đã chốt | I39: Trưởng BP CCKB + Quản trị | M39: Trao đổi nghiệp vụ Sơn Cảng, 10-11/10/2026 | N39: Cần làm rõ | O39: F=B tính giá mới khi rút, nhưng G “tùy A và B”; cần chính sách mặc định theo phiên và lựa chọn điều chỉnh giá.
A40: E14 | B40: 03. Cắm/rút điện | C40: P1 | D40: Có yêu cầu lưu vị trí/ổ cắm/số công tơ/ảnh khi cắm, hay chỉ theo container và giờ thực tế? | E40: A. Chỉ cont và giờ; B. Thêm vị trí ổ cắm; C. Thêm ảnh/công tơ; ghi rõ. | F40: A | G40: có thể cho an ninh điền cái này cx được để họ nhớ, sau này làm sơ đồ cũng dễ | H40: Đã chốt | I40: Trưởng BP CCKB + An ninh | M40: Trao đổi nghiệp vụ Sơn Cảng, 10-11/10/2026 | N40: Đủ rõ để đặc tả | O40: Có lựa chọn được người dùng đánh dấu đã chốt; giữ nguyên câu trả lời và ghi chú.
A41: E15 | B41: 03. Cắm/rút điện | C41: P1 | D41: Ai là người được phép sửa danh mục đơn giá cắm điện và có cần TBP/BLĐ phê duyệt mức giá mới? | E41: A. Quản trị; B. Trưởng BP CCKB; C. CCKB đề xuất, Quản trị duyệt; khác. | F41: A | H41: Đã chốt | I41: Trưởng BP CCKB + Quản trị | M41: Trao đổi nghiệp vụ Sơn Cảng, 10-11/10/2026 | N41: Đủ rõ để đặc tả | O41: Có lựa chọn được người dùng đánh dấu đã chốt; giữ nguyên câu trả lời và ghi chú.
...

Sheet 02_DA_CHOT
A1: QUYẾT ĐỊNH ĐÃ XÁC NHẬN — BAO GỒM PHẢN HỒI V1
A2: Các mục còn cần điều kiện chi tiết được ghi rõ trong cột Quy tắc; không suy diễn là hoàn thành mọi phân quyền và ngoại lệ.
A4: STT | B4: Nhóm | C4: Quyết định đã xác nhận | D4: Giá trị / Quy tắc | E4: Trách nhiệm | F4: Trạng thái | G4: Nguồn xác nhận
A5: 1 | B5: Phạm vi | C5: PWA/Web thay thế AppSheet Sơn Cảng sau nghiệm thu | D5: V1 có kiểm soát cổng, container, phí và cắm điện | E5: CNTT / Các BP | F5: Đã chốt | G5: Trao đổi do Sơn Cảng xác nhận, tháng 10/2026
A6: 2 | B6: Phạm vi | C6: Xây phân hệ cắm điện container ngay trong V1 | D6: Dùng chung dữ liệu container và cơ chế thanh toán | E6: CCKB / An ninh | F6: Đã chốt | G6: Trao đổi do Sơn Cảng xác nhận, tháng 10/2026
A7: 3 | B7: Nghiệp vụ | C7: Xe/container quản lý tách lượt, có thể khác xe vào/xe ra | D7: Xe hạ container rồi ra; container tiếp tục ở trong bãi | E7: An ninh / Điều phối | F7: Đã chốt | G7: Trao đổi do Sơn Cảng xác nhận, tháng 10/2026
A8: 4 | B8: Nghiệp vụ | C8: Xe có container có thể ra cùng container hoặc hạ container | D8: Việc hạ không quyết định phát sinh phí lưu | E8: An ninh | F8: Đã chốt | G8: Trao đổi do Sơn Cảng xác nhận, tháng 10/2026
A9: 5 | B9: Thông tin xe | C9: Xe có mang container mới yêu cầu nhập SO_CONTAINER | D9: Loại xe bo không mang container không bị hỏi số container | E9: An ninh | F9: Đã chốt | G9: Trao đổi do Sơn Cảng xác nhận, tháng 10/2026
A10: 6 | B10: Thông tin xe | C10: Xe bo ba bánh không yêu cầu biển số xe | D10: Phí vé vào 40.000 đồng/lượt | E10: An ninh | F10: Đã chốt | G10: Trao đổi do Sơn Cảng xác nhận, tháng 10/2026
A11: 7 | B11: Vé xe | C11: Xe container lạnh vé vào 250.000 đồng/lượt | D11: Dùng mã CONT_LANH trong PRICE_LIST | E11: An ninh | F11: Đã chốt | G11: Trao đổi do Sơn Cảng xác nhận, tháng 10/2026
A12: 8 | B12: Vé xe | C12: Đầu kéo không container vé vào 0 đồng/lượt | D12: Dùng mã DAU_KEO trong PRICE_LIST mới | E12: An ninh | F12: Đã chốt | G12: Trao đổi do Sơn Cảng xác nhận, tháng 10/2026
A13: 9 | B13: Vé xe | C13: Xe bo 3 chân / 4 chân vé vào 200.000 đồng/lượt | D13: Dùng mã riêng theo PRICE_LIST | E13: An ninh | F13: Đã chốt | G13: Trao đổi do Sơn Cảng xác nhận, tháng 10/2026
A14: 10 | B14: Vé xe | C14: Xe bo 8 tấn/2 chân vé vào 100.000 đồng/lượt | D14: Dùng mã XE_BO_8_TAN_2_CHAN | E14: An ninh | F14: Đã chốt | G14: Trao đổi do Sơn Cảng xác nhận, tháng 10/2026
A15: 11 | B15: Vé xe | C15: Xe sang tải (tạp) vé vào 0 đồng/lượt | D15: Dùng mã XE_SANG_TAI | E15: An ninh | F15: Đã chốt | G15: Trao đổi do Sơn Cảng xác nhận, tháng 10/2026
A16: 12 | B16: Lưu container | C16: Phí lưu tính theo CONTAINER, không phải lưu XE | D16: Bắt đầu GIO_CONT_VAO, kết thúc GIO_CONT_RA | E16: CCKB | F16: Đã chốt | G16: Trao đổi do Sơn Cảng xác nhận, tháng 10/2026
... A55: 51 | B55: Hóa đơn | C55: Bước tiếp nhận vé cần lưu thông tin khách/lái xe phục vụ hóa đơn | D55: Yêu cầu công nợ/hóa đơn tích hợp Kế toán dự kiến triển khai giai đoạn sau | E55: An ninh + Kế toán | F55: Đã chốt phần nguyên tắc | G55: V1 đã trả lời: T12 (G)

Sheet 03_BANG_GIA
A1: BẢNG GIÁ HIỆN HÀNH VÀ DÒNG GIÁ BỔ SUNG
A2: Giữ nguyên 8 dòng PRICE_LIST do Sơn Cảng cung cấp; bổ sung 2 mã cắm điện và 1 mã phạt mất vé để chuẩn hóa, cần xác nhận mã mới.
A4: MA_LOAI | B4: TEN_LOAI | C4: DOI_TUONG | D4: LOAI_PHI | E4: DON_GIA (VND) | F4: DON_VI_TINH | G4: MOC_BAT_DAU | H4: MOC_KET_THUC | I4: SO_DEM_MIEN_PHI | J4: HOAT_DONG | K4: THU_TU | L4: GHI_CHU | M4: Nguồn | N4: Phê duyệt mã thêm | O4: Ghi chú cập nhật (điền)
A5: CONT_LANH | B5: Xe container lạnh | C5: Phương tiện | D5: Vé vào | E5: 250000 | F5: Lượt | I5: 0 | J5: TRUE | K5: 1 | L5: Thu vé khi xe vào có kéo container | M5: PRICE_LIST gốc | N5: Đã xác nhận
A6: DAU_KEO | B6: Đầu kéo không container | C6: Phương tiện | D6: Vé vào | E6: 0 | F6: Lượt | I6: 0 | J6: TRUE | K6: 2 | L6: Thu vé khi đầu kéo vào không có container | M6: PRICE_LIST gốc | N6: Đã xác nhận
A7: XE_BO_4_CHAN | B7: Xe bo 4 chân | C7: Phương tiện | D7: Vé vào | E7: 200000 | F7: Lượt | I7: 0 | J7: TRUE | K7: 3 | L7: Thu tiền vé khi xe vào | M7: PRICE_LIST gốc | N7: Đã xác nhận
A8: XE_BO_3_CHAN | B8: Xe bo 3 chân | C8: Phương tiện | D8: Vé vào | E8: 200000 | F8: Lượt | I8: 0 | J8: TRUE | K8: 4 | L8: Thu tiền vé khi xe vào | M8: PRICE_LIST gốc | N8: Đã xác nhận
A9: XE_BO_8_TAN_2_CHAN | B9: Xe bo 8 tấn/2 chân | C9: Phương tiện | D9: Vé vào | E9: 100000 | F9: Lượt | I9: 0 | J9: TRUE | K9: 5 | L9: Thu tiền vé khi xe vào | M9: PRICE_LIST gốc | N9: Đã xác nhận
A10: XE_BO_3_BANH | B10: Xe bo 3 bánh | C10: Phương tiện | D10: Vé vào | E10: 40000 | F10: Lượt | I10: 0 | J10: TRUE | K10: 6 | L10: Thu tiền vé khi xe vào; không yêu cầu biển số | M10: PRICE_LIST gốc | N10: Đã xác nhận
A11: XE_SANG_TAI | B11: Xe sang tải (tạp) | C11: Phương tiện | D11: Vé vào | E11: 0 | F11: Lượt | I11: 0 | J11: TRUE | K11: 7 | L11: Miễn phí, chỉ kiểm soát xe ra vào | M11: PRICE_LIST gốc | N11: Đã xác nhận
A12: LUU_CONTAINER | B12: Phí lưu container | C12: Container | D12: Lưu đêm | E12: 100000 | F12: Đêm | G12: 22:00 | H12: 06:00 | I12: 1 | J12: TRUE | K12: 8 | L12: Phí lưu bằng (số đêm trừ một) nhân 100.000; kể cả không hạ cont | M12: PRICE_LIST gốc + chốt sau | N12: Đã xác nhận
A13: DIEN_CONT_GIO | B13: Cắm điện theo giờ | C13: Container | D13: Cắm điện | E13: 100000 | F13: Giờ | I13: 0 | J13: TRUE | K13: 9 | L13: Làm tròn lên từng 15 phút; CCKB nhập giờ thực tế | M13: Bổ sung theo chốt mới | N13: Mã đề xuất cần duyệt
A14: DIEN_CONT_LIEN_TUC | B14: Cắm điện liên tục | C14: Container | D14: Cắm điện | E14: 100000 | F14: Giờ | I14: 0 | J14: TRUE | K14: 10 | L14: Làm tròn lên từng 15 phút; CCKB nhập giờ thực tế | M14: Bổ sung theo chốt mới | N14: Mã đề xuất cần duyệt
A15: PHAT_MAT_VE | B15: Phạt mất liên 02 vé xe | C15: Vé xe | D15: Phạt | E15: 250000 | F15: Trường hợp | I15: 0 | J15: TRUE | K15: 11 | L15: Mức tiền theo thông báo; người trực tiếp thu còn cần chốt | M15: Bổ sung từ thông báo | N15: Mã đề xuất cần duyệt

Sheet 04_PHAN_QUYEN
A1: MA TRẬN QUYỀN THEO 07 VAI TRÒ — CẦN XÁC NHẬN
A2: Các cột quyền đang để trống vì đã chốt TRÁCH NHIỆM BỘ PHẬN nhưng chưa chốt từng quyền. Chọn Thực hiện / Xem / Phê duyệt / Không.
A4: Mã | B4: Nhóm | C4: Chức năng / thao tác | D4: Bộ phận trách nhiệm đã chốt | E4: NV An ninh | F4: TBP An ninh | G4: NV CCKB | H4: TBP CCKB | I4: NV Điều phối | J4: TBP Điều phối | K4: Quản trị | L4: Ghi chú cần xác nhận (điền) | M4: Trạng thái
A5: Q01 | B5: Cổng vào | C5: Tạo lượt xe vào và giờ vào | D5: An ninh | M5: Chờ xác nhận
A6: Q02 | B6: Cổng vào | C6: Thu tiền vé vào, đính kèm ảnh chuyển khoản | D6: An ninh | M6: Chờ xác nhận
A7: Q03 | B7: Cổng vào | C7: Sửa biển số / loại xe / GIO_VAO | D7: Chờ phân quyền | M7: Chờ xác nhận
A8: Q04 | B8: Cổng vào | C8: Tạo/điều chỉnh số vé giấy | D8: An ninh | M8: Chờ xác nhận
A9: Q05 | B9: Container | C9: Tạo lượt container vào, ghi GIO_CONT_VAO | D9: An ninh | M9: Chờ xác nhận
A10: Q06 | B10: Container | C10: Thay đổi số container sau khi lưu | D10: Chờ phân quyền | E10: Thực hiện | F10: Thực hiện | L10: Đã xác nhận cấp quyền cho An ninh sửa số cont và báo CCKB. Các ngoại lệ đã thanh toán/đã xuất vẫn cần chốt. | M10: Chờ xác nhận
A11: Q07 | B11: Container | C11: Xác nhận hạ/xếp container (quản lý vị trí) | D11: Chờ phân quyền | M11: Chờ xác nhận
A12: Q08 | B12: Điều phối | C12: Cập nhật HÀNG/RỖNG | D12: Điều phối | M12: Chờ xác nhận
A13: Q09 | B13: Điều phối | C13: Sửa HÀNG/RỖNG sau khi đã ra | D13: Chờ phân quyền | M13: Chờ xác nhận
A14: Q10 | B14: Cắm điện | C14: Tạo yêu cầu cắm/rút từ khách hàng | D14: CCKB | M14: Chờ xác nhận
A15: Q11 | B15: Cắm điện | C15: Thực hiện cắm/rút điện tại hiện trường | D15: An ninh | M15: Chờ xác nhận
A16: Q12 | B16: Cắm điện | C16: Nhập GIO_CAM_THUC_TE | D16: CCKB | M16: Chờ xác nhận
A17: Q13 | B17: Cắm điện | C17: Nhập GIO_RUT_THUC_TE | D17: CCKB | M17: Chờ xác nhận
A18: Q14 | B18: Cắm điện | C18: Sửa giờ cắm/rút trước khi thu | D18: CCKB | M18: Chờ xác nhận
A19: Q15 | B19: Cắm điện | C19: Đề nghị sửa giờ sau khi đã thu | D19: CCKB | M19: Chờ xác nhận
A20: Q16 | B20: Cắm điện | C20: Phê duyệt chênh lệch sau khi thu | D20: Chờ phân quyền | M20: Chờ xác nhận
A21: Q17 | B21: Cắm điện | C21: Quản lý danh mục giá điện và ngày hiệu lực | D21: Chờ phân quyền | M21: Chờ xác nhận
A22: Q18 | B22: Thanh toán | C22: Tính/thu phí lưu container | D22: CCKB | M22: Chờ xác nhận
... A34: Q30 | B34: Báo cáo | C34: Xuất Excel/báo cáo phục vụ kiểm toán | D34: Chờ phân quyền | M34: Chờ xác nhận
A35: Q31 | B35: Cắm điện dự kiến | C35: Tạo yêu cầu cắm điện cho cont chưa vào (một hoặc nhiều số) | D35: CCKB | L35: Đề xuất NV/TBP CCKB thực hiện; chưa chốt chi tiết vai trò. | M35: Chờ xác nhận
A36: Q32 | B36: Cắm điện dự kiến | C36: Sửa hoặc hủy yêu cầu điện dự kiến khi khách đổi số cont | D36: CCKB | L36: Cần chốt quyền, lưu lịch sử và thông báo An ninh. | M36: Chờ xác nhận
A37: Q33 | B37: Cổng vào | C37: Xem cảnh báo danh sách cont có yêu cầu cắm điện dự kiến | D37: An ninh | L37: Đã chốt An ninh cần nhìn thấy khi nhập container. | M37: Chờ xác nhận
A38: Q34 | B38: Cổng vào | C38: Xác nhận ghép số cont dự kiến với lượt cont vào thực tế | D38: An ninh + CCKB | L38: Quy tắc ghép tự động/thủ công chưa chốt. | M38: Chờ xác nhận
A39: Q35 | B39: Container | C39: Sửa số cont đã nhập sai và ghi nhận đã báo CCKB | D39: An ninh | L39: Đã chốt bộ phận; cần quy định khi đã thu tiền. | M39: Chờ xác nhận
A40: Q36 | B40: Container | C40: Tiếp nhận cảnh báo sửa số cont, kiểm tra và cập nhật yêu cầu dự kiến | D40: CCKB | L40: Quy trình xác nhận và phương thức báo lại cần chốt. | M40: Chờ xác nhận
A41: Q37 | B41: Chứng cứ | C41: Đính kèm ảnh/video nhận diện sai số container | D41: An ninh / CCKB | L41: Cần chốt bắt buộc hay không, kích thước và lưu trữ. | M41: Chờ xác nhận
A42: Q38 | B42: Ngoại lệ | C42: Duyệt sửa số cont sau thanh toán/đã ra và đối soát phí | D42: Chờ phân quyền | L42: Không được tự động đổi lịch sử khoản thu đã chốt. | M42: Chờ xác nhận
A43: Q39 | B43: Đối soát | C43: Xem và xác nhận đã xử lý cảnh báo sai số cont/không ghép được yêu cầu dự kiến | D43: CCKB + An ninh | L43: Cần trạng thái giao việc và phản hồi đóng thông báo. | M43: Chờ xác nhận

Sheet 05_KICH_BAN
A1: BỘ TÌNH HUỐNG ĐỂ XÁC NHẬN QUY TẮC VÀ NGHIỆM THU
A2: Kịch bản chưa được chốt được ghi rõ là “Cần xác nhận”; ô màu vàng để bộ phận điền kết quả chuẩn trước khi kiểm thử.
A4: Mã | B4: Phân hệ | C4: Tình huống nghiệp vụ | D4: Dữ liệu đầu vào minh họa | E4: Kỳ vọng hiện có / cần xác nhận | F4: Mức độ | G4: Kết quả chuẩn Sơn Cảng (điền) | H4: Tình trạng | I4: Ghi chú kiểm thử (điền)
A5: TC01 | B5: Vé | C5: Xe container lạnh có cont vào bãi | D5: Loại CONT_LANH, có SO_CONTAINER | E5: Vé vào 250.000đ; An ninh thu | F5: P1 | H5: Có quy tắc
A6: TC02 | B6: Vé | C6: Đầu kéo vào không cont, ra không cont | D6: DAU_KEO | E6: Vé vào 0đ; không phí lưu cont | F6: P1 | H6: Có quy tắc
A7: TC03 | B7: Vé | C7: Đầu kéo vào không cont, ra kéo cont lưu trong bãi | D7: DAU_KEO + SO_CONTAINER_RA | E7: ĐÃ CHỐT V01: không thu thêm 250.000đ ở lượt ra; container vẫn được tính phí lưu theo lượt. | F7: P0 | H7: Có quy tắc
A8: TC04 | B8: Vé | C8: Xe bo ba bánh không có biển số | D8: XE_BO_3_BANH, BIEN_SO_XE rỗng | E8: Tạo mã lượt; tiền vé 40.000đ | F8: P1 | H8: Có quy tắc
A9: TC05 | B9: Vé | C9: Xe bo 3 chân vào không cont | D9: XE_BO_3_CHAN | E9: Vé vào 200.000đ; không phí lưu cont | F9: P1 | H9: Có quy tắc
A10: TC06 | B10: Vé | C10: Lái xe không xuất trình được liên 02 | D10: Vé đã phát, liên 02 mất | E10: Mức phạt 250.000đ; người xác nhận/thu CHƯA CHỐT | F10: P0 | H10: Chờ duyệt
A11: TC07 | B11: Lưu cont | C11: Cont ở trên xe, không hạ, ở qua 3 kỳ đêm | D11: 10/10 20:00 → 13/10 08:00 | E11: 3 đêm; miễn 1; thu 200.000đ | F11: P1 | H11: Có quy tắc
A12: TC08 | B12: Lưu cont | C12: Cont đã hạ, xe đầu vào ra một mình | D12: Xe A ra; cont còn trong bãi | E12: Cont vẫn tiếp tục tính phí đến GIO_CONT_RA | F12: P1 | H12: Có quy tắc
A13: TC09 | B13: Lưu cont | C13: Xe B đến kéo cont đã do xe A đưa vào | D13: ID_VEHICLE_VAO khác ID_VEHICLE_RA | E13: Phí tính cho cùng lượt cont, không khởi tạo lại GIO_CONT_VAO | F13: P1 | H13: Có quy tắc
A14: TC10 | B14: Lưu cont | C14: Cont vào và ra trong ngày, trước 22:00 | D14: 10/10 08:00 → 10/10 20:00 | E14: ĐÃ CHỐT L05=B: SO_DEM_LUU hiển thị tối thiểu 1 (miễn phí); tiền lưu 0đ. | F14: P0 | H14: Có quy tắc
A15: TC11 | B15: Lưu cont | C15: Ra đúng mốc 22:00 | D15: 10/10 20:00 → 10/10 22:00 | E15: ĐÃ CHỐT L01=A: ra đúng 22:00 ghi nhận một kỳ đêm (miễn đêm đầu). | F15: P0 | H15: Có quy tắc
A16: TC12 | B16: Lưu cont | C16: Ra đúng mốc 06:00 | D16: 10/10 23:00 → 11/10 06:00 | E16: ĐÃ CHỐT L02=A: ra đúng 06:00 vẫn tính thuộc kỳ đêm vừa kết thúc. | F16: P0 | H16: Có quy tắc
... A31: TC27 | B31: Mất mạng | C31: An ninh cho xe ra khi PWA offline | D31: Điện thoại không có internet | E31: ĐÃ CHỐT K03=A: offline cho phép ghi nhận chờ đồng bộ; không tự xác nhận ra cổng offline. | F31: P0 | H31: Có quy tắc
A32: TC28 | B32: Yêu cầu điện dự kiến | C32: CCKB tiếp nhận trước yêu cầu cắm A, B, C; chưa xe nào vào | D32: CCKB tạo yêu cầu cho A/B/C | E32: Đã chốt: ghi danh sách dự kiến; không tạo lượt cont vào và không tính tiền điện/lưu trước khi có sự kiện thực tế. | F32: P0 | H32: Có quy tắc | I32: Bổ sung nghiệp vụ mới ngày 11/10/2026
A33: TC29 | B33: Yêu cầu điện dự kiến | C33: Chỉ container A trong danh sách A,B,C đi vào cổng | D33: A vào trước, B/C chưa tới | E33: Đã chốt: An ninh thấy cảnh báo yêu cầu dự kiến. Đề xuất: chỉ A ghép lượt thực tế, B/C vẫn chờ. | F33: P0 | H33: Chờ duyệt | I33: Bổ sung nghiệp vụ mới ngày 11/10/2026
A34: TC30 | B34: Yêu cầu điện dự kiến | C34: An ninh gõ trùng số container trong yêu cầu dự kiến | D34: CCKB dự kiến ABCU1234567, thực tế ABCU1234567 | E34: Đã chốt: hiển thị yêu cầu dự kiến để đối chiếu. Cơ chế ghép tự động/chọn tay cần xác nhận PR04. | F34: P0 | H34: Chờ duyệt | I34: Bổ sung nghiệp vụ mới ngày 11/10/2026
A35: TC31 | B35: Đối chiếu số cont | C35: Số container khách báo trước sai 1 ký tự so với số thực tế | D35: ABCU1234567 vs ACBU1234567 | E35: Đề xuất: cảnh báo mã gần giống, không tự ghép/đổi số khi khác; An ninh xác minh thực tế. | F35: P0 | H35: Chờ duyệt | I35: Bổ sung nghiệp vụ mới ngày 11/10/2026
A36: TC32 | B36: Sửa số cont | C36: An ninh thấy số đã nhập nhầm sau khi chụp ảnh hiện trường | D36: Số dự kiến/nhập khác ảnh cont thực tế | E36: Đã chốt: An ninh có thể sửa và báo lại CCKB; đề xuất giữ giá trị cũ/mới, người sửa, lý do và chứng cứ. | F36: P0 | H36: Có quy tắc | I36: Bổ sung nghiệp vụ mới ngày 11/10/2026
A37: TC33 | B37: Sửa số cont | C37: Khách ban đầu báo sai số cont, CCKB nhập sai yêu cầu dự kiến | D37: Khách nhắn A, thực tế B | E37: Đề xuất: CCKB cập nhật yêu cầu dự kiến theo số thực tế; không tạo trùng lượt cont. | F37: P0 | H37: Chờ duyệt | I37: Bổ sung nghiệp vụ mới ngày 11/10/2026
A38: TC34 | B38: Liên kết điện | C38: Sau khi đã nhập giờ cắm, An ninh phát hiện video chụp cont khác số đã liên kết | D38: Phiên điện nối nhầm cont A thay vì B | E38: Đề xuất: quy trình sửa liên kết phiên điện có kiểm soát; audit, thông báo CCKB và tính lại liên quan. | F38: P0 | H38: Chờ duyệt | I38: Bổ sung nghiệp vụ mới ngày 11/10/2026
A39: TC35 | B39: Sau khi thu tiền | C39: Sửa số cont sau khi phí điện/lưu đã thu hoặc CCKB đã duyệt cho ra | D39: Trạng thái tiền đã thu/đã duyệt | E39: Đề xuất: không thay ngầm giao dịch tài chính; cần tái kiểm tra và xác nhận ngoại lệ. | F39: P0 | H39: Chờ duyệt | I39: Bổ sung nghiệp vụ mới ngày 11/10/2026
A40: TC36 | B40: Dữ liệu trùng | C40: Có hai yêu cầu dự kiến cùng số cont nhưng khác khách hàng hoặc 2 cont cùng mã đang trong bãi | D40: ABCU1234567 lặp trong hai yêu cầu | E40: Đề xuất: cảnh báo trùng và yêu cầu phân định đúng lượt thực tế; không tự nhập/thu trùng. | F40: P0 | H40: Chờ duyệt | I40: Bổ sung nghiệp vụ mới ngày 11/10/2026
A41: TC37 | B41: Yêu cầu điện dự kiến | C41: Container đã được đăng ký dự kiến nhưng khách hủy/không đến | D41: Dự kiến A/B/C, hủy C | E41: Đề xuất: cho hủy dòng C, giữ lịch sử; không thay dữ liệu A/B và không tạo phí. | F41: P1 | H41: Chờ duyệt | I41: Bổ sung nghiệp vụ mới ngày 11/10/2026
A42: TC38 | B42: Tình huống mạng | C42: An ninh tra cứu yêu cầu dự kiến nhưng mất Internet tại cổng | D42: PWA offline, cần xác nhận cont | E42: Cần chốt: thông báo dữ liệu có thể chưa cập nhật; không tự ghép hay xác nhận tài chính/cho ra khi offline. | F42: P0 | H42: Chờ duyệt | I42: Bổ sung nghiệp vụ mới ngày 11/10/2026
A43: TC39 | B43: Thanh toán | C43: CCKB duyệt cho container ra dù chưa ghi nhận đủ tiền | D43: Container còn 200.000đ tiền điện; CCKB cho phép ra | E43: Cho thao tác duyệt thủ công với cảnh báo Chưa thu; quyền/lý do/nhật ký còn cần chốt OUT01 | F43: P0 | H43: Chờ duyệt | I43: V1 T08, OUT01
... A48: TC44 | B48: Sai số cont | C48: An ninh phát hiện số cont sai sau khi CCKB đã duyệt ra tay | D48: Sai một số; trước đó CCKB duyệt chưa thu đủ | E48: Giữ cảnh báo, thông báo CCKB đối chiếu khoản thu/trạng thái ra; phương thức chặn hoặc cho ra cần chốt SC08 | F48: P0 | H48: Chờ duyệt | I48: V1 T08/D06 + SC08

Sheet 06_MAPPING_V1
A1: DANH MỤC CỘT DỮ LIỆU APPSHEET V1 — ĐỐI CHIẾU PWA
A2: 32 cột VEHICLE + 25 cột CONTAINER từ tệp gốc. Ánh xạ PWA là đề xuất kỹ thuật, không tự coi là đã phê duyệt.
A4: STT | B4: Bảng V1 | C4: Cột gốc V1 | D4: Hướng lưu trên PWA (đề xuất) | E4: Cách chuyển dữ liệu | F4: Mức ưu tiên | G4: Quyết định ánh xạ (điền) | H4: Ghi chú chuyển đổi (điền)
A5: 1 | B5: VEHICLE | C5: ID | D5: VEHICLE | E5: Giữ khóa nguồn/legacy ID; kiểm tra trùng. | F5: P0
A6: 2 | B6: VEHICLE | C6: BIEN_SO_XE | D6: VEHICLE_VISITS | E6: Giữ thời điểm thực tế, nguồn người thao tác; tách trạng thái tài chính và ra cổng. | F6: P1
A7: 3 | B7: VEHICLE | C7: LOAI_XE | D7: VEHICLE_VISITS | E7: Giữ thời điểm thực tế, nguồn người thao tác; tách trạng thái tài chính và ra cổng. | F7: P1
A8: 4 | B8: VEHICLE | C8: SO_CONTAINER_VAO | D8: CONTAINER / CONTAINER_VISITS | E8: Lưu lượt container độc lập, liên kết lượt xe; kiểm tra lịch sử nhiều lượt. | F8: P1
A9: 5 | B9: VEHICLE | C9: ID_CONTAINER_VAO | D9: Ghi chú nghiệp vụ / audit | E9: Cần xem ý nghĩa và ánh xạ theo hồ sơ nguồn. | F9: P1
A10: 6 | B10: VEHICLE | C10: GIO_VAO | D10: VEHICLE_VISITS | E10: Giữ thời điểm thực tế, nguồn người thao tác; tách trạng thái tài chính và ra cổng. | F10: P0
A11: 7 | B11: VEHICLE | C11: NGUOI_VAO | D11: VEHICLE_VISITS | E11: Giữ thời điểm thực tế, nguồn người thao tác; tách trạng thái tài chính và ra cổng. | F11: P1
A12: 8 | B12: VEHICLE | C12: SO_CONTAINER_RA | D12: CONTAINER / CONTAINER_VISITS | E12: Lưu lượt container độc lập, liên kết lượt xe; kiểm tra lịch sử nhiều lượt. | F12: P1
A13: 9 | B13: VEHICLE | C13: ID_CONTAINER_RA | D13: Ghi chú nghiệp vụ / audit | E13: Cần xem ý nghĩa và ánh xạ theo hồ sơ nguồn. | F13: P1
A14: 10 | B14: VEHICLE | C14: GIO_RA | D14: VEHICLE_VISITS | E14: Giữ thời điểm thực tế, nguồn người thao tác; tách trạng thái tài chính và ra cổng. | F14: P0
A15: 11 | B15: VEHICLE | C15: NGUOI_RA | D15: VEHICLE_VISITS | E15: Giữ thời điểm thực tế, nguồn người thao tác; tách trạng thái tài chính và ra cổng. | F15: P1
A16: 12 | B16: VEHICLE | C16: TIEN_VE_GOC | D16: CHARGES / PAYMENTS / AUDIT_LOG | E16: Tách số tiền phải thu và tiền thực nhận, giữ bằng chứng và lịch sử. | F16: P1
... A61: 57 | B61: CONTAINER | C61: TINH_TRANG_HANG_CONT | D61: CONTAINER / CONTAINER_VISITS | E61: Lưu lượt container độc lập, liên kết lượt xe; kiểm tra lịch sử nhiều lượt. | F61: P1

Sheet 07_TAI_KHOAN
A1: DANH SÁCH USERS APPSHEET — PHỤC VỤ ÁNH XẠ PHÂN QUYỀN
A2: Giữ nguyên EMAIL / HO_TEN / VAI_TRO / HOAT_DONG người dùng đã cung cấp. Cột mới để Sơn Cảng nhập, không tự cấp thêm quyền.
A4: STT | B4: EMAIL V1 | C4: HỌ TÊN V1 | D4: VAI_TRÒ V1 | E4: HOẠT ĐỘNG V1 | F4: Bộ phận PWA (điền) | G4: Vai trò PWA (điền) | H4: Hoạt động mới (điền) | I4: Ghi chú xác nhận (điền)
A5: 1 | B5: thanhngx12@gmail.com | C5: Nguyễn Xuân Thành | D5: Quản trị | E5: TRUE
A6: 2 | B6: anninh.talunglogistics@gmail.com | C6: Nhân viên An ninh 01 | D6: Nhân viên An ninh | E6: TRUE
A7: 3 | B7: thaild@talunglogistics.com | C7: Trưởng bộ phận An ninh | D7: Trưởng bộ phận An ninh | E7: TRUE
A8: 4 | B8: vietnq.talunglogistics@gmail.com | C8: Nhân viên An ninh 02 | D8: Nhân viên An ninh | E8: TRUE
A9: 5 | B9: dieuphoi.talunglogistics@gmail.com | C9: Điều phối | D9: Điều phối | E9: TRUE
A10: 6 | B10: gate.talunglogistics@gmail.com | C10: Điều phối | D10: Điều phối | E10: TRUE

Sheet 08_DOI_SOAT
A1: CÁC MẪU DỮ LIỆU CŨ CẦN ĐỐI CHIẾU TRƯỚC CHUYỂN ĐỔI
A2: Dấu hiệu chưa nhất quán chỉ là mục cần xác minh, KHÔNG tự kết luận đã thu thiếu hoặc nhập sai. Không tự sửa chứng từ gốc.
A4: STT | B4: Đối tượng | C4: ID / Số container | D4: Dữ liệu trong bảng | E4: Dấu hiệu cần kiểm tra | F4: Tác động tiềm ẩn | G4: Bộ phận đối chiếu | H4: Kết luận đối chiếu (điền) | I4: Trạng thái
A5: 1 | B5: CONTAINER | C5: CCLU8578039 | D5: TIEN_LUU_PHAI_THU = 1.000.000đ; GHI_CHU_THU_LUU = "900k" | E5: Cần xác nhận số tiền thực nhận là 900k hay 1 triệu; không suy ra từ trạng thái Đã thu. | F5: Tránh xuất sai doanh thu/công nợ khi chuyển. | G5: CCKB + Kế toán | I5: Chưa đối soát
A6: 2 | B6: CONTAINER | C6: KKFU2636586 | D6: TIEN_LUU_PHAI_THU = 2.900.000đ; ghi chú 2.700.000đ; GIO_CONT_RA 26/09/2026 | E6: Ghi chú nêu "ra 20:20 23/9" khác ngày ra trong cột; cần đối chiếu vé và tiền nhận. | F6: Sai mốc ra có thể thay đổi số đêm và phí. | G6: An ninh + CCKB + Kế toán | I6: Chưa đối soát
A7: 3 | B7: CONTAINER | C7: WHLU7751030 | D7: TIEN_LUU_PHAI_THU = 900.000đ; ghi chú "Hùng thu 800k k ghi sổ" | E7: Cần kiểm tra tiền đã thu nhưng chưa vào sổ hay mới là ghi chú ngoài hệ thống. | F7: Tránh ghi nhận trùng hoặc bỏ sót khoản thu. | G7: CCKB + Kế toán | I7: Chưa đối soát
A8: 4 | B8: VEHICLE | C8: 15C09113 / ID 43da6325 | D8: SO_CONTAINER_VAO = TDRU0708408; SO_CONTAINER_RA = TDRU0708407 | E8: Số container vào và ra lệch 1 chữ số; cần xác nhận thay cont thực tế hay nhập nhầm. | F8: Ảnh hưởng liên kết lượt cont và thu phí. | G8: An ninh + Điều phối | I8: Chưa đối soát
A9: 5 | B9: VEHICLE | C9: ID 71562ccf | D9: XE_BO_3_BANH, BIEN_SO_XE để trống | E9: Dữ liệu chứng minh cần xử lý xe không có biển số thật. | F9: PWA không bắt buộc biển số và cần mã lượt độc lập. | G9: An ninh | I9: Chưa đối soát
A10: 6 | B10: VEHICLE | C10: ID ee310485, 2beb741a | D10: XE_BO_3_BANH, BIEN_SO_XE là "BO BA BANH" / "XE BA BANH" | E10: Bản ghi loại xe chứa mô tả thay biển số; khi chuyển cần chuẩn hóa rỗng, nhưng chỉ sau kiểm tra. | F10: Tránh coi chữ tự do là biển số phương tiện. | G10: An ninh + CNTT | I10: Chưa đối soát
A11: 7 | B11: VEHICLE | C11: Các dòng ghi "Khắc phục đồng bộ" | D11: Xe ra đã được cập nhật giờ ra sau dữ liệu container | E11: Cần phát hiện xe và cont đã ra thực tế nhưng không đồng nhất thời gian/bản ghi. | F11: PWA phải khóa giao dịch ra xe/cont đồng bộ. | G11: An ninh + CNTT | I11: Chưa đối soát

Sheet 09_TINH_DIEN
A1: MÔ PHỎNG QUY TẮC TIỀN ĐIỆN — LÀM TRÒN 15 PHÚT
A2: Thay đổi đơn giá và bước làm tròn trong ô vàng để kiểm thử. Đây là bản mô phỏng; không phải bảng thu tiền thực tế.
A4: Đơn giá (VND/giờ) | B4: 100000
A5: Bước làm tròn (phút) | B5: 15
A8: STT | B8: Giờ cắm thực tế (điền) | C8: Giờ rút thực tế (điền) | D8: Số phút thực tế | E8: Số phút tính tiền | F8: Giờ tính tiền | G8: Đơn giá (VNĐ/giờ) | H8: Thành tiền (VND)
A9: 1 | B9: 46306.354 | C9: 46306.558 | D9: =IF(OR(B9="",C9="",C9<=B9),"",ROUND((C9-B9)*1440,0)) | E9: =IF(D9="","",ROUNDUP(D9/$B$5,0)*$B$5) | F9: =IF(E9="","",E9/60) | G9: =IF($B$4="","",$B$4) | H9: =IF(OR(F9="",G9=""),"",ROUND(F9*G9,0))
A10: 2 | B10: 46306.354 | C10: 46306.365 | D10: =IF(OR(B10="",C10="",C10<=B10),"",ROUND((C10-B10)*1440,0)) | E10: =IF(D10="","",ROUNDUP(D10/$B$5,0)*$B$5) | F10: =IF(E10="","",E10/60) | G10: =IF($B$4="","",$B$4) | H10: =IF(OR(F10="",G10=""),"",ROUND(F10*G10,0))
A11: 3 | B11: 46306.354 | C11: 46306.365 | D11: =IF(OR(B11="",C11="",C11<=B11),"",ROUND((C11-B11)*1440,0)) | E11: =IF(D11="","",ROUNDUP(D11/$B$5,0)*$B$5) | F11: =IF(E11="","",E11/60) | G11: =IF($B$4="","",$B$4) | H11: =IF(OR(F11="",G11=""),"",ROUND(F11*G11,0))
A12: 4 | B12: 46306.354 | C12: 46306.396 | D12: =IF(OR(B12="",C12="",C12<=B12),"",ROUND((C12-B12)*1440,0)) | E12: =IF(D12="","",ROUNDUP(D12/$B$5,0)*$B$5) | F12: =IF(E12="","",E12/60) | G12: =IF($B$4="","",$B$4) | H12: =IF(OR(F12="",G12=""),"",ROUND(F12*G12,0))
A13: 5 | B13: 46306.354 | C13: 46306.397 | D13: =IF(OR(B13="",C13="",C13<=B13),"",ROUND((C13-B13)*1440,0)) | E13: =IF(D13="","",ROUNDUP(D13/$B$5,0)*$B$5) | F13: =IF(E13="","",E13/60) | G13: =IF($B$4="","",$B$4) | H13: =IF(OR(F13="",G13=""),"",ROUND(F13*G13,0))
A14: 6 | B14: 46306.354 | C14: 46306.542 | D14: =IF(OR(B14="",C14="",C14<=B14),"",ROUND((C14-B14)*1440,0)) | E14: =IF(D14="","",ROUNDUP(D14/$B$5,0)*$B$5) | F14: =IF(E14="","",E14/60) | G14: =IF($B$4="","",$B$4) | H14: =IF(OR(F14="",G14=""),"",ROUND(F14*G14,0))
A15: 7 | B15: 46306.944 | C15: 46307.153 | D15: =IF(OR(B15="",C15="",C15<=B15),"",ROUND((C15-B15)*1440,0)) | E15: =IF(D15="","",ROUNDUP(D15/$B$5,0)*$B$5) | F15: =IF(E15="","",E15/60) | G15: =IF($B$4="","",$B$4) | H15: =IF(OR(F15="",G15=""),"",ROUND(F15*G15,0))
A16: 8 | B16: 46306.354 | C16: 46306.522 | D16: =IF(OR(B16="",C16="",C16<=B16),"",ROUND((C16-B16)*1440,0)) | E16: =IF(D16="","",ROUNDUP(D16/$B$5,0)*$B$5) | F16: =IF(E16="","",E16/60) | G16: =IF($B$4="","",$B$4) | H16: =IF(OR(F16="",G16=""),"",ROUND(F16*G16,0))
A19: Nguyên tắc: | B19: CCKB nhập giờ thực tế; hệ thống tính thời lượng và làm tròn LÊN theo từng 15 phút, tính theo đơn giá phiên cắm.
A21: CHÚ Ý: các câu hỏi về giây, thời lượng tối thiểu, sửa sau khi thu và thay đổi giá trong khi cắm vẫn nằm trong tab 01_CAU_HOI.

Sheet 10_DU_KIEN_SUA_SO_CONT
A1: YÊU CẦU ĐIỆN TRƯỚC KHI CONTAINER VÀO & SỬA SỐ CONTAINER
A2: Phân tách thông tin khách hàng thông báo trước, container đã vào thật và thao tác sửa sai — chỉ các mục ghi ĐÃ CHỐT mới là yêu cầu xác nhận.
A4: I. QUYẾT ĐỊNH MỚI VÀ PHẠM VI
A5: Mã | B5: Nội dung | C5: Trạng thái | D5: Quy tắc nghiệp vụ | E5: Giải pháp triển khai đề xuất | F5: Cần xác nhận thêm
A6: CN-01 | B6: Có yêu cầu điện dự kiến trước khi container vào | C6: Đã chốt | D6: CCKB nhận từ khách trước danh sách cont A/B/C, được ghi yêu cầu ngay. | E6: Lưu bản ghi dự kiến, không tự tạo lượt container vào, không ghi giờ vào và không tính phí. | F6: Cách nhóm A/B/C vào phiếu
A7: CN-02 | B7: An ninh nhìn thấy dự kiến lúc tiếp nhận | C7: Đã chốt | D7: Khi nhập số cont tại cổng, An ninh phải chú ý thông tin yêu cầu điện dự kiến. | E7: Hiển thị thẻ Chờ cắm điện / Đã đặt trước; gợi ý ghép và đối chiếu số thật. | F7: Quy tắc ghép số đầy đủ/7 số cuối
A8: CN-03 | B8: An ninh sửa số cont sai và báo lại CCKB | C8: Đã chốt | D8: Sai có thể xuất phát từ khách, CCKB hoặc hiện trường. Ảnh/video giúp phát hiện sai. | E8: Thao tác Sửa số container, ghi cũ/mới/lý do/người sửa; tạo cảnh báo CCKB. | F8: Quy trình sau khi thu/đã ra, bằng chứng bắt buộc?
A9: CN-04 | B9: Tách dự kiến khỏi thực tế | C9: Đề xuất chờ chốt | D9: Tạo yêu cầu điện trước không được làm tăng số cont thật đang nằm bãi. | E9: Mỗi dòng dự kiến chỉ liên kết tới ID lượt container khi xe/cont được ghi nhận vào cổng. | F9: Cách xác nhận liên kết và hết hạn dự kiến
A12: II. LUỒNG NHẬN YÊU CẦU ĐIỆN TRƯỚC KHI XE VÀO
A13: Bước | B13: Bộ phận | C13: Trạng thái đề xuất | D13: Thao tác nghiệp vụ | E13: Dữ liệu hiển thị/được lưu | F13: Lưu ý
A14: 1 | B14: CCKB | C14: Dự kiến / Chờ container vào | D14: Nhận thông tin khách hàng cho A, B, C; tạo yêu cầu cắm điện dự kiến. | E14: Số cont dự kiến, khách hàng, hình thức, người ghi nhận, giờ tiếp nhận; giờ dự kiến nếu có. | F14: Không cần GIO_CONT_VAO
A15: 2 | B15: An ninh | C15: Kiểm tra yêu cầu dự kiến | D15: Nhập loại xe, biển số, số cont thực tế lúc xe đến; xem cảnh báo các yêu cầu chờ. | E15: Hiển thị đúng số cont và các mã gần giống; tránh nhầm lẫn khi nhập 11 ký tự. | F15: Khi mã khác nhau phải đối chiếu ảnh/video timestamp; không tự ghép hai mã gần giống.
A16: 3 | B16: An ninh + CCKB | C16: Đã vào / Chờ cắm | D16: Đối chiếu số cont thực tế, xác nhận ghép với dòng dự kiến A (nếu phù hợp). | E16: ID lượt cont thực tế được liên kết với dòng yêu cầu A; B/C vẫn chờ. | F16: Chỉ tạo giờ vào khi cont thực vào
A17: 4 | B17: An ninh | C17: Đã thực hiện cắm (ngoài hiện trường) | D17: Thực hiện cắm theo yêu cầu; báo giờ thực tế qua Zalo/nhóm. | E17: Ảnh/video nếu có; người thực hiện thực tế; giờ báo. | F17: Không ép An ninh tự nhập giờ cắm PWA
A18: 5 | B18: CCKB | C18: Đang cắm / Đã rút / Chờ thu | D18: Nhập giờ cắm/rút từ thông tin An ninh báo, sửa được khi xác minh sai. | E18: Phiên điện liên kết với ID lượt cont, tính phí tròn mỗi 15 phút. | F18: Thu sau rút hoặc khi cont xuất theo phương án C
A19: 6 | B19: CCKB + An ninh | C19: Đủ điều kiện thanh toán → Đã xuất | D19: CCKB chốt phí hợp lệ, An ninh xác nhận xe/container thực ra. | E19: Chốt GIO_CONT_RA, lịch sử phí điện/lưu và người thực hiện. | F19: Tách duyệt tài chính và xác nhận thực ra
A22: III. LUỒNG SỬA SAI SỐ CONTAINER KHI CÓ ẢNH/VIDEO HOẶC KHÁCH BÁO NHẦM
A23: Bước | B23: Người phát hiện | C23: Trạng thái đề xuất | D23: Thao tác sửa/xác minh | E23: Dữ liệu bắt buộc đề xuất | F23: Điểm kiểm soát
A24: 1 | B24: An ninh / CCKB | C24: Phát hiện sai | D24: Đối chiếu mã 11 ký tự trên container hoặc chứng cứ hiện trường với dữ liệu dự kiến/đang lưu. | E24: Số cũ, số quan sát, nguồn đối chiếu; ảnh/video nếu có. | F24: Không âm thầm đổi liên kết sang container khác
A25: 2 | B25: An ninh | C25: Báo sửa số cont | D25: Chọn lượt cont đang có; nhập số đúng + lý do; lưu và báo CCKB. | E25: Người sửa, thời gian, số trước/sau, nguồn báo. | F25: V1 D06: TBP sửa trực tiếp; người dùng yêu cầu An ninh sửa và báo CCKB, nhưng quyền sửa sau thu còn mở.
A26: 3 | B26: PWA | C26: Chờ CCKB kiểm tra | D26: Sinh thông báo trong PWA về số cont đã sửa cho CCKB; gắn với yêu cầu điện/phiên điện. | E26: Mã cảnh báo, số cũ/mới, ID lượt cont, ảnh/video, người sửa. | F26: Zalo tự động là tính năng phải chốt riêng
A27: 4 | B27: CCKB | C27: Đã xác minh / Cần bổ sung | D27: Đối chiếu yêu cầu khách, cập nhật số cont dự kiến và liên kết đúng phiên điện. | E27: Người xác minh, ghi chú, lịch sử thay đổi. | F27: Không tạo lượt lưu/phiên cắm trùng
A28: 5 | B28: TBP có thẩm quyền | C28: Ngoại lệ sau thu / đã xuất | D28: Nếu tiền đã thu hoặc đã phê duyệt ra, tạo xử lý chênh lệch/đối soát. | E28: Giữ giao dịch cũ; ghi bút toán điều chỉnh nếu có. | F28: T08 cho duyệt xuất ngoại lệ khi chưa thu; nếu sai cont phải báo CCKB đối chiếu, không tự đổi khoản đã thu.
A31: IV. MÔ HÌNH DỮ LIỆU GỢI Ý — KHÔNG TẠO CONTAINER GIẢ
A32: Bảng / đối tượng | B32: Vai trò | C32: Trạng thái | D32: Liên kết | E32: Các trường trọng yếu | F32: Lưu ý
A33: CAM_DIEN_REQUESTS | B33: Phiếu khách yêu cầu điện | C33: Dự kiến | D33: Yêu cầu chung của khách hàng | E33: ID, khách hàng, người tiếp nhận, giờ tiếp nhận, yêu cầu chung | F33: Có thể có nhiều container A/B/C
A34: CAM_DIEN_REQUEST_ITEMS | B34: Các dòng container dự kiến | C34: Chờ vào / Đã vào / Hủy | D34: ID_REQUEST; ID_CONTAINER_VISIT có thể rỗng trước khi cont vào | E34: SO_CONTAINER_DU_KIEN, loại cắm, ghi chú, trạng thái khớp | F34: Một dòng dự kiến không phải một lượt cont vào thật
A35: CONTAINER / CONTAINER_VISITS | B35: Container và lượt vào thực tế | C35: Đang trong bãi / Đã xuất | D35: ID lượt xe vào/ra + ID lượt container | E35: SO_CONTAINER_THUC_TE, GIO_CONT_VAO, GIO_CONT_RA | F35: Dùng giờ thực tế để tính phí lưu
A36: CAM_DIEN_CONT | B36: Phiên cắm/rút thực tế | C36: Tiếp nhận / Đang cắm / Đã rút | D36: ID_CONTAINER_VISIT; có thể biết yêu cầu điện nguồn | E36: GIO_CAM_THUC_TE, GIO_RUT_THUC_TE, TONG_PHUT_TINH_TIEN | F36: CCKB nhập/sửa; làm tròn lên 15 phút
A37: CONTAINER_CORRECTIONS | B37: Đề nghị/sự kiện sửa số cont | C37: Báo sửa / Chờ xác minh / Đã xác minh | D37: ID_CONTAINER_VISIT, ID_REQUEST_ITEM | E37: SO_CU, SO_MOI, LY_DO, NGUOI_SUA, THOI_GIAN, BANG_CHUNG | F37: Giữ lịch sử & phản hồi CCKB
A38: APP_NOTIFICATIONS | B38: Thông báo liên bộ phận | C38: Chưa xem / Đã xem / Đã xử lý | D38: Tham chiếu sự kiện cont/yêu cầu | E38: Nguồn thông báo, người nhận, loại cảnh báo, giờ đọc | F38: Không tự coi tin nhắn Zalo là đồng bộ PWA
A41: V. DANH SÁCH CÂU HỎI CẦN TRẢ LỜI Ở TAB 01_CAU_HOI
A42: PR01/PR02/SC01 đã xác nhận. PR03–PR07, SC02–SC08 vẫn mở. D06/V09/T08/T15 ở bản V1 đã trả lời và cần đối chiếu khi xử lý sửa số cont.
A44: Nguyên tắc an toàn: sửa số container không làm thay đổi ID lượt; tiền đã thu không bị ghi đè âm thầm; thông báo CCKB cần có trạng thái đã xem/đã xử lý.

Sheet 11_RA_SOAT_V1
A1: CÁC ĐIỂM CẦN LÀM RÕ SAU KHI ĐỌC FILE V1 ĐÃ TRẢ LỜI
A2: Không tự sửa câu trả lời của người dùng. Lọc P0 để ưu tiên những điểm ảnh hưởng tiền, quyền ra cổng và điều chỉnh số container.
A4: STT | B4: Mã câu hỏi | C4: Ưu tiên | D4: Nhóm nghiệp vụ | E4: Nội dung cần chốt | F4: Người dùng đã chọn | G4: Ghi chú trả lời nguyên văn | H4: Điểm cần làm rõ / mâu thuẫn | I4: Ý kiến bổ sung (điền) | J4: Trạng thái rà soát (điền)
A5: 1 | B5: CNT01 | C5: P0 | D5: 02. Lưu container | E5: Phí lưu chốt theo giờ CCKB duyệt/thu hay giờ container ra thật? Ai kiểm tra tiền cuối cùng: An ninh hay CCKB? | H5: Câu hỏi mới từ phần nghiệp vụ phát sinh; chờ bạn trả lời. | J5: Chờ bổ sung
A6: 2 | B6: D06 | C6: P0 | D6: 06. Điều phối / container | E6: Khi số container gõ nhầm hoặc khác so với trên vé, người nào được xác nhận sửa thông tin? | F6: A | G6: TBP thì sửa trực tiếp | H6: F=A NV An ninh sửa; G TBP được sửa trực tiếp; yêu cầu mới An ninh sửa và báo CCKB. Cần ngưỡng quyền sau thu/ra. | J6: Chờ bổ sung
A7: 3 | B7: E06 | C7: P0 | D7: 03. Cắm/rút điện | E7: Sau khi đã thu tiền điện, CCKB được sửa giờ tới mức nào và quy trình phê duyệt chênh lệch? | F7: B | G7: A Và B | H7: F=B nhưng G=A và B: vừa NV đề nghị/TBP duyệt vừa TBP sửa trực tiếp; cần điều kiện khi nào mỗi cách. | J7: Chờ bổ sung
A8: 4 | B8: E07 | C8: P0 | D8: 03. Cắm/rút điện | E8: Phiên điện còn trạng thái Đang cắm trên PWA nhưng thực tế đã rút, container có được xuất không? | F8: A | G8: Làm cách nào thoai r mái hon, CCKB cứ xác định xe đã được ra thì ra, nếu xe ra đến cổng mà chưa thấy được ra thì gọi hoặc nhắn nhóm có CCKB | H8: F=A buộc cập nhật xong trước ra, nhưng G ưu tiên CCKB xác nhận bằng tay và Zalo khi cần; cần cơ chế override có audit. | J8: Chờ bổ sung
A9: 5 | B9: E08 | C9: P0 | D9: 03. Cắm/rút điện | E9: Khi không có mạng/không thể cập nhật giờ rút, cần quy trình bàn giao ngoài hệ thống và bổ sung dữ liệu như thế nào? | F9: A | G9: chỗ này chưa hiểu | H9: G ghi “chỗ này chưa hiểu”; không thể coi là quyết định đã chốt dù F=A. Cần giải thích quy trình offline và nhập bù. | J9: Chờ bổ sung
A10: 6 | B10: E09 | C10: P0 | D10: 03. Cắm/rút điện | E10: Tổng thời gian thực tế tính bằng giây hay phút? Ví dụ 4 giờ 00 phút 01 giây có làm tròn thành 4 giờ 15 phút không? | F10: Khác | G10: Hieện tại CCKB tự làm tròn | H10: G: CCKB tự làm tròn, trong khi đã chốt tính tròn lên mỗi 15 phút. Cần xác nhận tự tính mặc định + cho điều chỉnh thủ công. | J10: Chờ bổ sung
A11: 7 | B11: INV01 | C11: P0 | D11: 04. Thanh toán | E11: Khi An ninh nhận thông tin xuất hóa đơn tại cổng vào, những trường nào bắt buộc theo từng loại khách hàng? | H11: Câu hỏi mới từ phần nghiệp vụ phát sinh; chờ bạn trả lời. | J11: Chờ bổ sung
A12: 8 | B12: K01 | C12: P0 | D12: 08. Kỹ thuật / bảo mật | E12: Phần mềm chạy trên tên miền/subdomain nào và ai chịu trách nhiệm quản trị máy chủ? | H12: K01: ô lựa chọn thật sự để trống trong file V1, dù cột H được đánh dấu Đã chốt. Cần chọn tên miền/subdomain. | J12: Chờ bổ sung
A13: 9 | B13: L04 | C13: P0 | D13: 02. Lưu container | E13: CCKB đã duyệt thanh toán trước 22:00, nhưng container thực tế xuất sau 22:00 và phát sinh thêm kỳ đêm: quy trình cập nhật phí? | F13: B | G13: Vì nhiều lúc thanh toán và rút rồi nhưng chưa ra nhé | H13: F=B khóa phí tại giờ CCKB duyệt; T09 lại chọn tính lại tại lúc cont thực ra. Cần xác định mốc chốt phí sau 22:00. | J13: Chờ bổ sung
